Workbook

Sheet 대시보드
D3: 전사 경영성과 Factbook 개요 | U3: =YEAR('0. 개요'!AE2)&"-"&MONTH('0. 개요'!AE2) -> 2026-2
U4: =MONTH('0. 개요'!AE2) -> 2

Sheet 0. 개요
A2: =YEAR(AE2)&"년 "&MONTH(AE2)&"월 전사 경영 성과 Factbook" -> 2026년 2월 전사 경영 성과 Factbook | AC2: 기준월 : | AE2: 46054

Sheet 0. 목차
A2: 0. 목차 | AC2: 기준월 : | AE2: ='0. 개요'!AE2 -> 46054
A5: 순번 | C5: 구분 | F5: 상세 내용 | P5: 마감일시 | Z5: 페이지
A6: 1 | C6: 재무 | F6: ① 매출 (통신매출, 유통플랫폼사업매출) | K6: ② 판매비와 일반관리비 | P6: 21일 ~ 26일 (회계 결산 마감 이후 반영) | T6: • • • • • • • • • • • • • • • • • • • • • • • • • • • • • • • • • • | Z6: 1 ~ 3
F7: ③ 채널별 영업이익 | K7: ④ 주요 채널 상세 재무지표 요약
A8: 2 | C8: 무선가입자 | F8: ① 일반 후불 (전체) 가입자(CAPA) | K8: ② 일반 후불 (IoT) 가입자(CAPA) | P8: ~ 16일 | T8: • • • • • • • • • • • • • • • • • • • • • • • • • • • • • • • • • • | Z8: 4 ~ 5
F9: ③ 도소매 조직별 가입자(CAPA) | K9: ④ 채널별 판매 ARPU / 무선 증분 매출
A10: 2-(1) | C10: 무선가입자 (상세) | F10: ① 관리수수료 8.5% 대상 가입자(CAPA) | K10: ② 위탁 H/C 2.2% 대상 가입자(CAPA) | P10: ~ 16일 | T10: • • • • • • • • • • • • • • • • • • • • • • • • • • • • • • • • • • | Z10: 6 ~ 7
F11: ③ 채널별 일반 후불 (전체) 가입자(CAPA) | K11: ④ 채널별 무선 관리수수료
A12: 3 | C12: 유선가입자 | F12: ① 유선 전체 (I+TV) 가입자 | K12: ② 유선 순신규 (I+TV) 가입자 | P12: ~ 16일 | T12: • • • • • • • • • • • • • • • • • • • • • • • • • • • • • • • • • • | Z12: 8 ~ 9
F13: ③ 도소매 조직별 (I+TV) 가입자 | K13: ④ 유선 Quality 채널별 비중
A14: 3-(1) | C14: 유선가입자(상세) | F14: ① 채널별 인터넷 (I) 가입자 상세 | K14: ② 채널별 TV 가입자 상세 | P14: ~ 16일 | T14: • • • • • • • • • • • • • • • • • • • • • • • • • • • • • • • • • • | Z14: 10 ~ 11
F15: ③ 채널별 유선 관리수수료
A16: 4 | C16: 디지털 | F16: ① KT닷컴 운영 후불/ 유선 순신규 가입자 | K16: ② KT닷컴 전용 요고 요금제 실적 | P16: ~ 13일 (전월 가입자 / 인력 마감 이후) | T16: • • • • • • • • • • • • • • • • • • • • • • • • • • • • • • • • • • | Z16: 12
F17: ③ 라이브 방송 실적 | K17: ④ 영업센터 파트별 인력 현황
A18: 5 | C18: 소상공인 | F18: ① 전체 무선 후불 / 유선 순신규 가입자 | K18: ② 본부별 무선 후불 / 유선 순신규 가입자 | P18: ~ 13일 (전월 가입자 / 인력 마감 이후) | T18: • • • • • • • • • • • • • • • • • • • • • • • • • • • • • • • • • • | Z18: 13 ~ 14
F19: ③ 소상공인 전체 인력 현황 | K19: ④ 본부별 인력 충원 / 등급 / 포인트
A20: 6 | C20: B2B | F20: ① B2B 전체 유무선 가입자 실적 | K20: ② 기업영업 / 법인 영업 유무선 가입자 실적 | P20: ~ 13일 | T20: • • • • • • • • • • • • • • • • • • • • • • • • • • • • • • • • • • | Z20: 15
A21: 7 | C21: 유통플랫폼사업 | F21: ① 시연폰 사업 매입 / 매각 현황 | K21: ② 중고폰 사업 매입 / 매각 현황 | P21: 13일 ~ 18일 (전월 가입자 / 매출액 마감 이후) | T21: • • • • • • • • • • • • • • • • • • • • • • • • • • • • • • • • • • | Z21: 16
F22: ③ 코코넛 허브 가입 및 출고 현황 | K22: ④ 코코넛 Mall 이용자 및 매출액
A23: 8 | C23: 인프라 | F23: ① 소매 매장 조직별 인프라 현황 | K23: ② 매장 생산성 (후불 + 유선 순신규) | P23: ~ 16일 | T23: • • • • • • • • • • • • • • • • • • • • • • • • • • • • • • • • • • | Z23: 17
F24: ③ 도매센터 조직별 인프라 현황
A25: 9 | C25: 인력 | F25: ① 전사 인력 현황 | K25: ② 직급별 인력 현황 | P25: ~ 16일 | T25: • • • • • • • • • • • • • • • • • • • • • • • • • • • • • • • • • • | Z25: 18 ~ 20
F26: ③ 도소매 조직별 인력 현황
A27: 10 | C27: 영업품질 | F27: ① 도소매 R-VOC 인입 현황 | K27: ② 도소매 대외 민원 접수 / 귀책 건수 | P27: ~ 16일 (대외 민원 / 음성적 재가입은 익익월 산출) | T27: • • • • • • • • • • • • • • • • • • • • • • • • • • • • • • • • • • | Z27: 21 ~ 22
F28: ③ 도소매 불완전 판매 현황 | K28: ④ 도소매 음성적 재가입 현황
A29: 11 | C29: 재고 | F29: ① 단말 / 유선 재고 현황 | K29: ② 제조사별 직매입 현황 | P29: ~ 16일 | T29: • • • • • • • • • • • • • • • • • • • • • • • • • • • • • • • • • • | Z29: 23
F30: ③ 제조사별 판매 현황 (KT 내 비중) | K30: ④ 엣지프로젝트 수량 및 마진 현황
A31: 12 | C31: 기타지표 | F31: ① 지사별 TCSI 점수 현황 | K31: ② 전략 상품 판매 현황 | P31: ~ 16일 | T31: • • • • • • • • • • • • • • • • • • • • • • • • • • • • • • • • • • | Z31: 24

Sheet 1.재무
F1: CC | G1: BQ | H1: BR | I1: BS | J1: BT | K1: BU | L1: BV | M1: =R1 -> CU | N1: cd | O1: ce | P1: CR | Q1: CS | R1: CU | S1: CV | T1: CW | U1: CX | V1: 실적
A2: 1. 재무
E4: ※ 내부 도전목표 | G4: '25년 상반기 | N4: '26년 상반기 | R4: ='※ 재무_세부시트'!CU3 -> 연간누적실적(~2월)
A5: 구분 | E5: 설명 | F5: '25년 계 | G5: {=INDIRECT("'※ 재무_세부시트'!"&G$1&$V5, TRUE)} -> '25.1월 | H5: {=INDIRECT("'※ 재무_세부시트'!"&H$1&$V5, TRUE)} -> '25.2월 | I5: {=INDIRECT("'※ 재무_세부시트'!"&I$1&$V5, TRUE)} -> '25.3월 | J5: {=INDIRECT("'※ 재무_세부시트'!"&J$1&$V5, TRUE)} -> '25.4월 | K5: {=INDIRECT("'※ 재무_세부시트'!"&K$1&$V5, TRUE)} -> '25.5월 | L5: {=INDIRECT("'※ 재무_세부시트'!"&L$1&$V5, TRUE)} -> '25.6월 | M5: '26년 계 | N5: {=INDIRECT("'※ 재무_세부시트'!"&N$1&$V5, TRUE)} -> '26.1월 | O5: {=INDIRECT("'※ 재무_세부시트'!"&O$1&$V5, TRUE)} -> '26.2월 | P5: 전월대비 | Q5: 전년 동월대비 | R5: 누적 | S5: 목표대비 | T5: 달성률 | U5: 전년 동기대비 | V5: 4
A6: 총매출 (ⓐ+ⓑ+ⓒ+ⓓ) | F6: {=INDIRECT("'※ 재무_세부시트'!"&F$1&$V6, TRUE)} -> 7534.581 | G6: {=INDIRECT("'※ 재무_세부시트'!"&G$1&$V6, TRUE)} -> 560.63833 | H6: {=INDIRECT("'※ 재무_세부시트'!"&H$1&$V6, TRUE)} -> 1003.2939 | I6: {=INDIRECT("'※ 재무_세부시트'!"&I$1&$V6, TRUE)} -> 569.23055 | J6: {=INDIRECT("'※ 재무_세부시트'!"&J$1&$V6, TRUE)} -> 449.51814 | K6: {=INDIRECT("'※ 재무_세부시트'!"&K$1&$V6, TRUE)} -> 517.36254 | L6: {=INDIRECT("'※ 재무_세부시트'!"&L$1&$V6, TRUE)} -> 544.95947 | M6: {=INDIRECT("'※ 재무_세부시트'!"&M$1&$V6, TRUE)} -> 1266.7957 | ... U6: {=INDIRECT("'※ 재무_세부시트'!"&U$1&$V6, TRUE)} -> -297.13652 | V6: 5
B7: 상품매출 (ⓐ+ⓓ) | F7: {=INDIRECT("'※ 재무_세부시트'!"&F$1&$V7, TRUE)} -> 4676.9607 | G7: {=INDIRECT("'※ 재무_세부시트'!"&G$1&$V7, TRUE)} -> 377.4824 | H7: {=INDIRECT("'※ 재무_세부시트'!"&H$1&$V7, TRUE)} -> 737.1983 | I7: {=INDIRECT("'※ 재무_세부시트'!"&I$1&$V7, TRUE)} -> 368.49675 | J7: {=INDIRECT("'※ 재무_세부시트'!"&J$1&$V7, TRUE)} -> 243.45807 | K7: {=INDIRECT("'※ 재무_세부시트'!"&K$1&$V7, TRUE)} -> 287.03542 | L7: {=INDIRECT("'※ 재무_세부시트'!"&L$1&$V7, TRUE)} -> 319.55447 | M7: {=INDIRECT("'※ 재무_세부시트'!"&M$1&$V7, TRUE)} -> 796.36152 | ... U7: {=INDIRECT("'※ 재무_세부시트'!"&U$1&$V7, TRUE)} -> -318.31918 | V7: 6
B8: 상품원가 | F8: {=INDIRECT("'※ 재무_세부시트'!"&F$1&$V8, TRUE)} -> 5012.7115 | G8: {=INDIRECT("'※ 재무_세부시트'!"&G$1&$V8, TRUE)} -> 388.7483 | H8: {=INDIRECT("'※ 재무_세부시트'!"&H$1&$V8, TRUE)} -> 790.57614 | I8: {=INDIRECT("'※ 재무_세부시트'!"&I$1&$V8, TRUE)} -> 385.18887 | J8: {=INDIRECT("'※ 재무_세부시트'!"&J$1&$V8, TRUE)} -> 256.63171 | K8: {=INDIRECT("'※ 재무_세부시트'!"&K$1&$V8, TRUE)} -> 307.72262 | L8: {=INDIRECT("'※ 재무_세부시트'!"&L$1&$V8, TRUE)} -> 324.79942 | M8: {=INDIRECT("'※ 재무_세부시트'!"&M$1&$V8, TRUE)} -> 878.50721 | ... U8: {=INDIRECT("'※ 재무_세부시트'!"&U$1&$V8, TRUE)} -> -300.81723 | V8: 7
B9: 상품이익 | F9: {=INDIRECT("'※ 재무_세부시트'!"&F$1&$V9, TRUE)} -> -335.75085 | G9: {=INDIRECT("'※ 재무_세부시트'!"&G$1&$V9, TRUE)} -> -11.265901 | H9: {=INDIRECT("'※ 재무_세부시트'!"&H$1&$V9, TRUE)} -> -53.377835 | I9: {=INDIRECT("'※ 재무_세부시트'!"&I$1&$V9, TRUE)} -> -16.692117 | J9: {=INDIRECT("'※ 재무_세부시트'!"&J$1&$V9, TRUE)} -> -13.173643 | K9: {=INDIRECT("'※ 재무_세부시트'!"&K$1&$V9, TRUE)} -> -20.6872 | L9: {=INDIRECT("'※ 재무_세부시트'!"&L$1&$V9, TRUE)} -> -5.2449434 | M9: {=INDIRECT("'※ 재무_세부시트'!"&M$1&$V9, TRUE)} -> -82.145691 | ... U9: {=INDIRECT("'※ 재무_세부시트'!"&U$1&$V9, TRUE)} -> -17.501956 | V9: 8
B10: * 프리할부 | F10: {=INDIRECT("'※ 재무_세부시트'!"&F$1&$V10, TRUE)} -> 56.4834 | G10: {=INDIRECT("'※ 재무_세부시트'!"&G$1&$V10, TRUE)} -> 15.730997 | H10: {=INDIRECT("'※ 재무_세부시트'!"&H$1&$V10, TRUE)} -> 40.752403 | I10: {=INDIRECT("'※ 재무_세부시트'!"&I$1&$V10, TRUE)} -> 0 | J10: {=INDIRECT("'※ 재무_세부시트'!"&J$1&$V10, TRUE)} -> 0 | K10: {=INDIRECT("'※ 재무_세부시트'!"&K$1&$V10, TRUE)} -> 0 | L10: {=INDIRECT("'※ 재무_세부시트'!"&L$1&$V10, TRUE)} -> 0 | M10: {=INDIRECT("'※ 재무_세부시트'!"&M$1&$V10, TRUE)} -> 0 | ... U10: {=INDIRECT("'※ 재무_세부시트'!"&U$1&$V10, TRUE)} -> -56.4834 | V10: 9
B11: 통신 매출 (ⓐ+ⓑ) | F11: {=INDIRECT("'※ 재무_세부시트'!"&F$1&$V11, TRUE)} -> 6977.9968 | G11: {=INDIRECT("'※ 재무_세부시트'!"&G$1&$V11, TRUE)} -> 533.56526 | H11: {=INDIRECT("'※ 재무_세부시트'!"&H$1&$V11, TRUE)} -> 937.0369 | I11: {=INDIRECT("'※ 재무_세부시트'!"&I$1&$V11, TRUE)} -> 520.82451 | J11: {=INDIRECT("'※ 재무_세부시트'!"&J$1&$V11, TRUE)} -> 413.50723 | K11: {=INDIRECT("'※ 재무_세부시트'!"&K$1&$V11, TRUE)} -> 474.81409 | L11: {=INDIRECT("'※ 재무_세부시트'!"&L$1&$V11, TRUE)} -> 497.40316 | M11: {=INDIRECT("'※ 재무_세부시트'!"&M$1&$V11, TRUE)} -> 1224.1525 | ... U11: {=INDIRECT("'※ 재무_세부시트'!"&U$1&$V11, TRUE)} -> -246.44967 | V11: 10
B12: 상품매출(통신) ⓐ | F12: {=INDIRECT("'※ 재무_세부시트'!"&F$1&$V12, TRUE)} -> 4166.8023 | G12: {=INDIRECT("'※ 재무_세부시트'!"&G$1&$V12, TRUE)} -> 355.07525 | H12: {=INDIRECT("'※ 재무_세부시트'!"&H$1&$V12, TRUE)} -> 679.23028 | I12: {=INDIRECT("'※ 재무_세부시트'!"&I$1&$V12, TRUE)} -> 321.5338 | J12: {=INDIRECT("'※ 재무_세부시트'!"&J$1&$V12, TRUE)} -> 213.07458 | K12: {=INDIRECT("'※ 재무_세부시트'!"&K$1&$V12, TRUE)} -> 246.36239 | L12: {=INDIRECT("'※ 재무_세부시트'!"&L$1&$V12, TRUE)} -> 274.80847 | M12: {=INDIRECT("'※ 재무_세부시트'!"&M$1&$V12, TRUE)} -> 758.76916 | ... U12: {=INDIRECT("'※ 재무_세부시트'!"&U$1&$V12, TRUE)} -> -275.53637 | V12: 11
B13: 수수료매출(통신) ⓑ | F13: {=INDIRECT("'※ 재무_세부시트'!"&F$1&$V13, TRUE)} -> 2811.1945 | G13: {=INDIRECT("'※ 재무_세부시트'!"&G$1&$V13, TRUE)} -> 178.49001 | H13: {=INDIRECT("'※ 재무_세부시트'!"&H$1&$V13, TRUE)} -> 257.80661 | I13: {=INDIRECT("'※ 재무_세부시트'!"&I$1&$V13, TRUE)} -> 199.29071 | J13: {=INDIRECT("'※ 재무_세부시트'!"&J$1&$V13, TRUE)} -> 200.43265 | K13: {=INDIRECT("'※ 재무_세부시트'!"&K$1&$V13, TRUE)} -> 228.4517 | L13: {=INDIRECT("'※ 재무_세부시트'!"&L$1&$V13, TRUE)} -> 222.5947 | M13: {=INDIRECT("'※ 재무_세부시트'!"&M$1&$V13, TRUE)} -> 465.38333 | ... U13: {=INDIRECT("'※ 재무_세부시트'!"&U$1&$V13, TRUE)} -> 29.0867 | V13: 12 | AB13: =SUM(G79:J79)/SUM(G13:J13,G50:J50) -> 0.10223774
C14: 정책수수료 | F14: {=INDIRECT("'※ 재무_세부시트'!"&F$1&$V14, TRUE)} -> 1729.0321 | G14: {=INDIRECT("'※ 재무_세부시트'!"&G$1&$V14, TRUE)} -> 95.784424 | H14: {=INDIRECT("'※ 재무_세부시트'!"&H$1&$V14, TRUE)} -> 166.62482 | I14: {=INDIRECT("'※ 재무_세부시트'!"&I$1&$V14, TRUE)} -> 110.26219 | J14: {=INDIRECT("'※ 재무_세부시트'!"&J$1&$V14, TRUE)} -> 103.99978 | K14: {=INDIRECT("'※ 재무_세부시트'!"&K$1&$V14, TRUE)} -> 141.27507 | L14: {=INDIRECT("'※ 재무_세부시트'!"&L$1&$V14, TRUE)} -> 121.71604 | M14: {=INDIRECT("'※ 재무_세부시트'!"&M$1&$V14, TRUE)} -> 291.61496 | ... U14: {=INDIRECT("'※ 재무_세부시트'!"&U$1&$V14, TRUE)} -> 29.205717 | V14: 13
C15: 유무선 | D15: 무선 | E15: 무선 판매관련 수수료 | F15: {=INDIRECT("'※ 재무_세부시트'!"&F$1&$V15, TRUE)} -> 1588.9649 | G15: {=INDIRECT("'※ 재무_세부시트'!"&G$1&$V15, TRUE)} -> 90.1286 | H15: {=INDIRECT("'※ 재무_세부시트'!"&H$1&$V15, TRUE)} -> 143.86298 | I15: {=INDIRECT("'※ 재무_세부시트'!"&I$1&$V15, TRUE)} -> 101.90002 | J15: {=INDIRECT("'※ 재무_세부시트'!"&J$1&$V15, TRUE)} -> 94.597902 | K15: {=INDIRECT("'※ 재무_세부시트'!"&K$1&$V15, TRUE)} -> 123.0866 | L15: {=INDIRECT("'※ 재무_세부시트'!"&L$1&$V15, TRUE)} -> 121.90912 | M15: {=INDIRECT("'※ 재무_세부시트'!"&M$1&$V15, TRUE)} -> 256.70963 | ... U15: {=INDIRECT("'※ 재무_세부시트'!"&U$1&$V15, TRUE)} -> 22.718057 | V15: 14
D16: 유선 | E16: 유선 판매관련 수수료 | F16: {=INDIRECT("'※ 재무_세부시트'!"&F$1&$V16, TRUE)} -> 140.06721 | G16: {=INDIRECT("'※ 재무_세부시트'!"&G$1&$V16, TRUE)} -> 5.6558239 | H16: {=INDIRECT("'※ 재무_세부시트'!"&H$1&$V16, TRUE)} -> 22.761839 | I16: {=INDIRECT("'※ 재무_세부시트'!"&I$1&$V16, TRUE)} -> 8.3621768 | J16: {=INDIRECT("'※ 재무_세부시트'!"&J$1&$V16, TRUE)} -> 9.4018754 | K16: {=INDIRECT("'※ 재무_세부시트'!"&K$1&$V16, TRUE)} -> 18.188465 | L16: {=INDIRECT("'※ 재무_세부시트'!"&L$1&$V16, TRUE)} -> -0.19308902 | M16: {=INDIRECT("'※ 재무_세부시트'!"&M$1&$V16, TRUE)} -> 34.905323 | ... U16: {=INDIRECT("'※ 재무_세부시트'!"&U$1&$V16, TRUE)} -> 6.4876597 | V16: 15
C17: 채널 | D17: 소매 | F17: {=INDIRECT("'※ 재무_세부시트'!"&F$1&$V17, TRUE)} -> 1174.2224 | G17: {=INDIRECT("'※ 재무_세부시트'!"&G$1&$V17, TRUE)} -> 49.550632 | H17: {=INDIRECT("'※ 재무_세부시트'!"&H$1&$V17, TRUE)} -> 135.13312 | I17: {=INDIRECT("'※ 재무_세부시트'!"&I$1&$V17, TRUE)} -> 97.077539 | J17: {=INDIRECT("'※ 재무_세부시트'!"&J$1&$V17, TRUE)} -> 93.319228 | K17: {=INDIRECT("'※ 재무_세부시트'!"&K$1&$V17, TRUE)} -> 120.71904 | L17: {=INDIRECT("'※ 재무_세부시트'!"&L$1&$V17, TRUE)} -> 87.744517 | M17: {=INDIRECT("'※ 재무_세부시트'!"&M$1&$V17, TRUE)} -> 149.3654 | ... R17: {=INDIRECT("'※ 재무_세부시트'!"&R$1&$V17, TRUE)} -> 149.3654 | U17: {=INDIRECT("'※ 재무_세부시트'!"&U$1&$V17, TRUE)} -> -35.318355 | V17: 16
D18: 도매 | F18: {=INDIRECT("'※ 재무_세부시트'!"&F$1&$V18, TRUE)} -> 14.56284 | G18: {=INDIRECT("'※ 재무_세부시트'!"&G$1&$V18, TRUE)} -> 1.8922512 | H18: {=INDIRECT("'※ 재무_세부시트'!"&H$1&$V18, TRUE)} -> 2.4818942 | I18: {=INDIRECT("'※ 재무_세부시트'!"&I$1&$V18, TRUE)} -> 0.70588278 | J18: {=INDIRECT("'※ 재무_세부시트'!"&J$1&$V18, TRUE)} -> 3.8676704 | K18: {=INDIRECT("'※ 재무_세부시트'!"&K$1&$V18, TRUE)} -> 0.20809046 | L18: {=INDIRECT("'※ 재무_세부시트'!"&L$1&$V18, TRUE)} -> 0.95145149 | M18: {=INDIRECT("'※ 재무_세부시트'!"&M$1&$V18, TRUE)} -> 2.0552305 | ... R18: {=INDIRECT("'※ 재무_세부시트'!"&R$1&$V18, TRUE)} -> 2.0552305 | U18: {=INDIRECT("'※ 재무_세부시트'!"&U$1&$V18, TRUE)} -> -2.3189149 | V18: 17
D19: 디지털 | F19: {=INDIRECT("'※ 재무_세부시트'!"&F$1&$V19, TRUE)} -> 364.0574 | G19: {=INDIRECT("'※ 재무_세부시트'!"&G$1&$V19, TRUE)} -> 24.53915 | H19: {=INDIRECT("'※ 재무_세부시트'!"&H$1&$V19, TRUE)} -> 24.976993 | I19: {=INDIRECT("'※ 재무_세부시트'!"&I$1&$V19, TRUE)} -> 8.5582728 | J19: {=INDIRECT("'※ 재무_세부시트'!"&J$1&$V19, TRUE)} -> 10.236852 | K19: {=INDIRECT("'※ 재무_세부시트'!"&K$1&$V19, TRUE)} -> 13.668366 | L19: {=INDIRECT("'※ 재무_세부시트'!"&L$1&$V19, TRUE)} -> 22.241117 | M19: {=INDIRECT("'※ 재무_세부시트'!"&M$1&$V19, TRUE)} -> 87.604155 | ... R19: {=INDIRECT("'※ 재무_세부시트'!"&R$1&$V19, TRUE)} -> 87.604155 | U19: {=INDIRECT("'※ 재무_세부시트'!"&U$1&$V19, TRUE)} -> 38.088012 | V19: 18
C20: 신사업 제외 | D20: 기타 | E20: B2B, 대형마트, 소상공인(25년~) 등 | F20: {=INDIRECT("'※ 재무_세부시트'!"&F$1&$V20, TRUE)} -> 394.21894 | G20: {=INDIRECT("'※ 재무_세부시트'!"&G$1&$V20, TRUE)} -> 18.417866 | H20: {=INDIRECT("'※ 재무_세부시트'!"&H$1&$V20, TRUE)} -> 28.322453 | I20: {=INDIRECT("'※ 재무_세부시트'!"&I$1&$V20, TRUE)} -> 23.0726 | J20: {=INDIRECT("'※ 재무_세부시트'!"&J$1&$V20, TRUE)} -> 21.997285 | K20: {=INDIRECT("'※ 재무_세부시트'!"&K$1&$V20, TRUE)} -> 29.546987 | L20: {=INDIRECT("'※ 재무_세부시트'!"&L$1&$V20, TRUE)} -> 48.038093 | M20: {=INDIRECT("'※ 재무_세부시트'!"&M$1&$V20, TRUE)} -> 70.375773 | ... R20: {=INDIRECT("'※ 재무_세부시트'!"&R$1&$V20, TRUE)} -> 70.375773 | U20: {=INDIRECT("'※ 재무_세부시트'!"&U$1&$V20, TRUE)} -> 23.635454 | V20: 19
D21: 순액처리 | F21: {=INDIRECT("'※ 재무_세부시트'!"&F$1&$V21, TRUE)} -> -218.02947 | G21: {=INDIRECT("'※ 재무_세부시트'!"&G$1&$V21, TRUE)} -> 1.3845247 | H21: {=INDIRECT("'※ 재무_세부시트'!"&H$1&$V21, TRUE)} -> -24.289645 | I21: {=INDIRECT("'※ 재무_세부시트'!"&I$1&$V21, TRUE)} -> -19.1521 | J21: {=INDIRECT("'※ 재무_세부시트'!"&J$1&$V21, TRUE)} -> -25.421259 | K21: {=INDIRECT("'※ 재무_세부시트'!"&K$1&$V21, TRUE)} -> -22.867412 | L21: {=INDIRECT("'※ 재무_세부시트'!"&L$1&$V21, TRUE)} -> -37.259143 | M21: {=INDIRECT("'※ 재무_세부시트'!"&M$1&$V21, TRUE)} -> -17.7856 | ... R21: {=INDIRECT("'※ 재무_세부시트'!"&R$1&$V21, TRUE)} -> -17.7856 | U21: {=INDIRECT("'※ 재무_세부시트'!"&U$1&$V21, TRUE)} -> 5.1195205 | V21: 20
C22: 관리수수료 | F22: {=INDIRECT("'※ 재무_세부시트'!"&F$1&$V22, TRUE)} -> 615.64255 | G22: {=INDIRECT("'※ 재무_세부시트'!"&G$1&$V22, TRUE)} -> 49.926384 | H22: {=INDIRECT("'※ 재무_세부시트'!"&H$1&$V22, TRUE)} -> 52.970258 | I22: {=INDIRECT("'※ 재무_세부시트'!"&I$1&$V22, TRUE)} -> 49.264715 | J22: {=INDIRECT("'※ 재무_세부시트'!"&J$1&$V22, TRUE)} -> 56.60334 | K22: {=INDIRECT("'※ 재무_세부시트'!"&K$1&$V22, TRUE)} -> 46.224101 | L22: {=INDIRECT("'※ 재무_세부시트'!"&L$1&$V22, TRUE)} -> 59.260522 | M22: {=INDIRECT("'※ 재무_세부시트'!"&M$1&$V22, TRUE)} -> 98.842087 | ... U22: {=INDIRECT("'※ 재무_세부시트'!"&U$1&$V22, TRUE)} -> -4.0545552 | V22: 21
C23: 유무선 | D23: 무선 | E23: 도매 HC 포함 | F23: {=INDIRECT("'※ 재무_세부시트'!"&F$1&$V23, TRUE)} -> 456.77828 | G23: {=INDIRECT("'※ 재무_세부시트'!"&G$1&$V23, TRUE)} -> 35.549797 | H23: {=INDIRECT("'※ 재무_세부시트'!"&H$1&$V23, TRUE)} -> 38.023935 | I23: {=INDIRECT("'※ 재무_세부시트'!"&I$1&$V23, TRUE)} -> 34.712852 | J23: {=INDIRECT("'※ 재무_세부시트'!"&J$1&$V23, TRUE)} -> 42.590158 | K23: {=INDIRECT("'※ 재무_세부시트'!"&K$1&$V23, TRUE)} -> 32.231392 | L23: {=INDIRECT("'※ 재무_세부시트'!"&L$1&$V23, TRUE)} -> 45.135692 | M23: {=INDIRECT("'※ 재무_세부시트'!"&M$1&$V23, TRUE)} -> 72.568051 | ... R23: {=INDIRECT("'※ 재무_세부시트'!"&R$1&$V23, TRUE)} -> 72.568051 | U23: {=INDIRECT("'※ 재무_세부시트'!"&U$1&$V23, TRUE)} -> -1.0056811 | V23: 22
D24: 유선 | F24: {=INDIRECT("'※ 재무_세부시트'!"&F$1&$V24, TRUE)} -> 68.278925 | G24: {=INDIRECT("'※ 재무_세부시트'!"&G$1&$V24, TRUE)} -> 5.8569293 | H24: {=INDIRECT("'※ 재무_세부시트'!"&H$1&$V24, TRUE)} -> 6.3086738 | I24: {=INDIRECT("'※ 재무_세부시트'!"&I$1&$V24, TRUE)} -> 6.4937648 | J24: {=INDIRECT("'※ 재무_세부시트'!"&J$1&$V24, TRUE)} -> 5.7726904 | K24: {=INDIRECT("'※ 재무_세부시트'!"&K$1&$V24, TRUE)} -> 5.6720753 | L24: {=INDIRECT("'※ 재무_세부시트'!"&L$1&$V24, TRUE)} -> 5.5931315 | M24: {=INDIRECT("'※ 재무_세부시트'!"&M$1&$V24, TRUE)} -> 10.24197 | ... R24: {=INDIRECT("'※ 재무_세부시트'!"&R$1&$V24, TRUE)} -> 10.24197 | U24: {=INDIRECT("'※ 재무_세부시트'!"&U$1&$V24, TRUE)} -> -1.9236332 | V24: 23
D25: 기타 | F25: {=INDIRECT("'※ 재무_세부시트'!"&F$1&$V25, TRUE)} -> 90.585339 | G25: {=INDIRECT("'※ 재무_세부시트'!"&G$1&$V25, TRUE)} -> 8.5196579 | H25: {=INDIRECT("'※ 재무_세부시트'!"&H$1&$V25, TRUE)} -> 8.6376484 | I25: {=INDIRECT("'※ 재무_세부시트'!"&I$1&$V25, TRUE)} -> 8.0580981 | J25: {=INDIRECT("'※ 재무_세부시트'!"&J$1&$V25, TRUE)} -> 8.2404921 | K25: {=INDIRECT("'※ 재무_세부시트'!"&K$1&$V25, TRUE)} -> 8.3206333 | L25: {=INDIRECT("'※ 재무_세부시트'!"&L$1&$V25, TRUE)} -> 8.5316987 | M25: {=INDIRECT("'※ 재무_세부시트'!"&M$1&$V25, TRUE)} -> 16.032065 | ... R25: {=INDIRECT("'※ 재무_세부시트'!"&R$1&$V25, TRUE)} -> 16.032065 | U25: {=INDIRECT("'※ 재무_세부시트'!"&U$1&$V25, TRUE)} -> -1.1252409 | V25: 24
C26: 항목 | D26: 무선후불 | E26: 관리수수료(6.5%)+H/C(2%) | F26: {=INDIRECT("'※ 재무_세부시트'!"&F$1&$V26, TRUE)} -> 417.986 | G26: {=INDIRECT("'※ 재무_세부시트'!"&G$1&$V26, TRUE)} -> 32.386892 | H26: {=INDIRECT("'※ 재무_세부시트'!"&H$1&$V26, TRUE)} -> 34.844772 | I26: {=INDIRECT("'※ 재무_세부시트'!"&I$1&$V26, TRUE)} -> 31.558001 | J26: {=INDIRECT("'※ 재무_세부시트'!"&J$1&$V26, TRUE)} -> 39.311072 | K26: {=INDIRECT("'※ 재무_세부시트'!"&K$1&$V26, TRUE)} -> 28.917454 | L26: {=INDIRECT("'※ 재무_세부시트'!"&L$1&$V26, TRUE)} -> 41.972786 | M26: {=INDIRECT("'※ 재무_세부시트'!"&M$1&$V26, TRUE)} -> 66.26524 | ... R26: {=INDIRECT("'※ 재무_세부시트'!"&R$1&$V26, TRUE)} -> 66.26524 | U26: {=INDIRECT("'※ 재무_세부시트'!"&U$1&$V26, TRUE)} -> -0.9664237 | V26: 25
D27: 2nd 등 기타단말 | E27: PAD, wearable 등 | F27: {=INDIRECT("'※ 재무_세부시트'!"&F$1&$V27, TRUE)} -> 17.832613 | G27: {=INDIRECT("'※ 재무_세부시트'!"&G$1&$V27, TRUE)} -> 1.4180424 | H27: {=INDIRECT("'※ 재무_세부시트'!"&H$1&$V27, TRUE)} -> 1.4337838 | I27: {=INDIRECT("'※ 재무_세부시트'!"&I$1&$V27, TRUE)} -> 1.4274744 | J27: {=INDIRECT("'※ 재무_세부시트'!"&J$1&$V27, TRUE)} -> 1.5287669 | K27: {=INDIRECT("'※ 재무_세부시트'!"&K$1&$V27, TRUE)} -> 1.5329222 | L27: {=INDIRECT("'※ 재무_세부시트'!"&L$1&$V27, TRUE)} -> 1.4180424 | M27: {=INDIRECT("'※ 재무_세부시트'!"&M$1&$V27, TRUE)} -> 3.021095 | ... R27: {=INDIRECT("'※ 재무_세부시트'!"&R$1&$V27, TRUE)} -> 3.021095 | U27: {=INDIRECT("'※ 재무_세부시트'!"&U$1&$V27, TRUE)} -> 0.16926879 | V27: 26
D28: IoT | E28: M2M 가입자 | F28: {=INDIRECT("'※ 재무_세부시트'!"&F$1&$V28, TRUE)} -> 20.959672 | G28: {=INDIRECT("'※ 재무_세부시트'!"&G$1&$V28, TRUE)} -> 1.7448628 | H28: {=INDIRECT("'※ 재무_세부시트'!"&H$1&$V28, TRUE)} -> 1.7453801 | I28: {=INDIRECT("'※ 재무_세부시트'!"&I$1&$V28, TRUE)} -> 1.7273761 | J28: {=INDIRECT("'※ 재무_세부시트'!"&J$1&$V28, TRUE)} -> 1.7503189 | K28: {=INDIRECT("'※ 재무_세부시트'!"&K$1&$V28, TRUE)} -> 1.781016 | L28: {=INDIRECT("'※ 재무_세부시트'!"&L$1&$V28, TRUE)} -> 1.7448628 | M28: {=INDIRECT("'※ 재무_세부시트'!"&M$1&$V28, TRUE)} -> 3.2817167 | ... R28: {=INDIRECT("'※ 재무_세부시트'!"&R$1&$V28, TRUE)} -> 3.2817167 | U28: {=INDIRECT("'※ 재무_세부시트'!"&U$1&$V28, TRUE)} -> -0.20852616 | V28: 27
D29: 인터넷 | F29: {=INDIRECT("'※ 재무_세부시트'!"&F$1&$V29, TRUE)} -> 43.773921 | G29: {=INDIRECT("'※ 재무_세부시트'!"&G$1&$V29, TRUE)} -> 3.8039285 | H29: {=INDIRECT("'※ 재무_세부시트'!"&H$1&$V29, TRUE)} -> 4.1171956 | I29: {=INDIRECT("'※ 재무_세부시트'!"&I$1&$V29, TRUE)} -> 4.3993616 | J29: {=INDIRECT("'※ 재무_세부시트'!"&J$1&$V29, TRUE)} -> 3.7391066 | K29: {=INDIRECT("'※ 재무_세부시트'!"&K$1&$V29, TRUE)} -> 3.6557821 | L29: {=INDIRECT("'※ 재무_세부시트'!"&L$1&$V29, TRUE)} -> 3.5924523 | M29: {=INDIRECT("'※ 재무_세부시트'!"&M$1&$V29, TRUE)} -> 6.2722214 | ... R29: {=INDIRECT("'※ 재무_세부시트'!"&R$1&$V29, TRUE)} -> 6.2722214 | U29: {=INDIRECT("'※ 재무_세부시트'!"&U$1&$V29, TRUE)} -> -1.6489027 | V29: 28
D30: TV | F30: {=INDIRECT("'※ 재무_세부시트'!"&F$1&$V30, TRUE)} -> 23.132791 | G30: {=INDIRECT("'※ 재무_세부시트'!"&G$1&$V30, TRUE)} -> 1.9646245 | H30: {=INDIRECT("'※ 재무_세부시트'!"&H$1&$V30, TRUE)} -> 2.1139593 | I30: {=INDIRECT("'※ 재무_세부시트'!"&I$1&$V30, TRUE)} -> 2.0006825 | J30: {=INDIRECT("'※ 재무_세부시트'!"&J$1&$V30, TRUE)} -> 1.944559 | K30: {=INDIRECT("'※ 재무_세부시트'!"&K$1&$V30, TRUE)} -> 1.9207854 | L30: {=INDIRECT("'※ 재무_세부시트'!"&L$1&$V30, TRUE)} -> 1.9006985 | M30: {=INDIRECT("'※ 재무_세부시트'!"&M$1&$V30, TRUE)} -> 3.6118059 | ... R30: {=INDIRECT("'※ 재무_세부시트'!"&R$1&$V30, TRUE)} -> 3.6118059 | U30: {=INDIRECT("'※ 재무_세부시트'!"&U$1&$V30, TRUE)} -> -0.46677782 | V30: 29
D31: 유선기타 | E31: SOIP, 기가아이즈, PSTN 등 | F31: {=INDIRECT("'※ 재무_세부시트'!"&F$1&$V31, TRUE)} -> 1.3722128 | G31: {=INDIRECT("'※ 재무_세부시트'!"&G$1&$V31, TRUE)} -> 0.08837641 | H31: {=INDIRECT("'※ 재무_세부시트'!"&H$1&$V31, TRUE)} -> 0.0775189 | I31: {=INDIRECT("'※ 재무_세부시트'!"&I$1&$V31, TRUE)} -> 0.093720582 | J31: {=INDIRECT("'※ 재무_세부시트'!"&J$1&$V31, TRUE)} -> 0.089024718 | K31: {=INDIRECT("'※ 재무_세부시트'!"&K$1&$V31, TRUE)} -> 0.095507827 | L31: {=INDIRECT("'※ 재무_세부시트'!"&L$1&$V31, TRUE)} -> 0.099980718 | M31: {=INDIRECT("'※ 재무_세부시트'!"&M$1&$V31, TRUE)} -> 0.35794262 | ... R31: {=INDIRECT("'※ 재무_세부시트'!"&R$1&$V31, TRUE)} -> 0.35794262 | U31: {=INDIRECT("'※ 재무_세부시트'!"&U$1&$V31, TRUE)} -> 0.19204731 | V31: 30
D32: 매장성수수료 | E32: CS업무처리 수수료 | F32: {=INDIRECT("'※ 재무_세부시트'!"&F$1&$V32, TRUE)} -> 9.1817721 | G32: {=INDIRECT("'※ 재무_세부시트'!"&G$1&$V32, TRUE)} -> 0.58253187 | H32: {=INDIRECT("'※ 재무_세부시트'!"&H$1&$V32, TRUE)} -> 0.66603878 | I32: {=INDIRECT("'※ 재무_세부시트'!"&I$1&$V32, TRUE)} -> 0.63645968 | J32: {=INDIRECT("'※ 재무_세부시트'!"&J$1&$V32, TRUE)} -> 0.59906741 | K32: {=INDIRECT("'※ 재무_세부시트'!"&K$1&$V32, TRUE)} -> 0.69777633 | L32: {=INDIRECT("'※ 재무_세부시트'!"&L$1&$V32, TRUE)} -> 0.75951674 | M32: {=INDIRECT("'※ 재무_세부시트'!"&M$1&$V32, TRUE)} -> 2.2593368 | ... R32: {=INDIRECT("'※ 재무_세부시트'!"&R$1&$V32, TRUE)} -> 2.2593368 | U32: {=INDIRECT("'※ 재무_세부시트'!"&U$1&$V32, TRUE)} -> 1.0107661 | V32: 31 | AA32: =H79/(H13+H50) -> 0.17528381 | AB32: =I79/(I13+I50) -> 0.10039511 | AC32: =J79/(J13+J50) -> 0.11980746
D33: 프라자3.0 | E33: 플라자 인건비 지원 | F33: {=INDIRECT("'※ 재무_세부시트'!"&F$1&$V33, TRUE)} -> 81.403567 | G33: {=INDIRECT("'※ 재무_세부시트'!"&G$1&$V33, TRUE)} -> 7.937126 | H33: {=INDIRECT("'※ 재무_세부시트'!"&H$1&$V33, TRUE)} -> 7.9716096 | I33: {=INDIRECT("'※ 재무_세부시트'!"&I$1&$V33, TRUE)} -> 7.4216384 | J33: {=INDIRECT("'※ 재무_세부시트'!"&J$1&$V33, TRUE)} -> 7.6414247 | K33: {=INDIRECT("'※ 재무_세부시트'!"&K$1&$V33, TRUE)} -> 7.622857 | L33: {=INDIRECT("'※ 재무_세부시트'!"&L$1&$V33, TRUE)} -> 7.772182 | M33: {=INDIRECT("'※ 재무_세부시트'!"&M$1&$V33, TRUE)} -> 13.772729 | ... R33: {=INDIRECT("'※ 재무_세부시트'!"&R$1&$V33, TRUE)} -> 13.772729 | U33: {=INDIRECT("'※ 재무_세부시트'!"&U$1&$V33, TRUE)} -> -2.136007 | V33: 32
C34: 채널 | D34: 소매 | E34: 관리수수료(점프업 제외), 매장성 수수료 | F34: {=INDIRECT("'※ 재무_세부시트'!"&F$1&$V34, TRUE)} -> 297.96476 | G34: {=INDIRECT("'※ 재무_세부시트'!"&G$1&$V34, TRUE)} -> 24.447654 | H34: {=INDIRECT("'※ 재무_세부시트'!"&H$1&$V34, TRUE)} -> 25.343579 | I34: {=INDIRECT("'※ 재무_세부시트'!"&I$1&$V34, TRUE)} -> 25.657675 | J34: {=INDIRECT("'※ 재무_세부시트'!"&J$1&$V34, TRUE)} -> 24.383282 | K34: {=INDIRECT("'※ 재무_세부시트'!"&K$1&$V34, TRUE)} -> 24.2331 | L34: {=INDIRECT("'※ 재무_세부시트'!"&L$1&$V34, TRUE)} -> 24.855322 | M34: {=INDIRECT("'※ 재무_세부시트'!"&M$1&$V34, TRUE)} -> 47.68084 | ... R34: {=INDIRECT("'※ 재무_세부시트'!"&R$1&$V34, TRUE)} -> 47.68084 | U34: {=INDIRECT("'※ 재무_세부시트'!"&U$1&$V34, TRUE)} -> -2.1103932 | V34: 33
D35: 도매 | F35: {=INDIRECT("'※ 재무_세부시트'!"&F$1&$V35, TRUE)} -> 107.70125 | G35: {=INDIRECT("'※ 재무_세부시트'!"&G$1&$V35, TRUE)} -> 9.0666553 | H35: {=INDIRECT("'※ 재무_세부시트'!"&H$1&$V35, TRUE)} -> 9.0830929 | I35: {=INDIRECT("'※ 재무_세부시트'!"&I$1&$V35, TRUE)} -> 8.5529126 | J35: {=INDIRECT("'※ 재무_세부시트'!"&J$1&$V35, TRUE)} -> 8.0079655 | K35: {=INDIRECT("'※ 재무_세부시트'!"&K$1&$V35, TRUE)} -> 7.6013216 | L35: {=INDIRECT("'※ 재무_세부시트'!"&L$1&$V35, TRUE)} -> 11.278029 | M35: {=INDIRECT("'※ 재무_세부시트'!"&M$1&$V35, TRUE)} -> 17.163483 | ... R35: {=INDIRECT("'※ 재무_세부시트'!"&R$1&$V35, TRUE)} -> 17.163483 | U35: {=INDIRECT("'※ 재무_세부시트'!"&U$1&$V35, TRUE)} -> -0.98626573 | V35: 34
D36: 디지털 | F36: {=INDIRECT("'※ 재무_세부시트'!"&F$1&$V36, TRUE)} -> 60.125982 | G36: {=INDIRECT("'※ 재무_세부시트'!"&G$1&$V36, TRUE)} -> 5.2481266 | H36: {=INDIRECT("'※ 재무_세부시트'!"&H$1&$V36, TRUE)} -> 5.3671954 | I36: {=INDIRECT("'※ 재무_세부시트'!"&I$1&$V36, TRUE)} -> 5.1954726 | J36: {=INDIRECT("'※ 재무_세부시트'!"&J$1&$V36, TRUE)} -> 5.066248 | K36: {=INDIRECT("'※ 재무_세부시트'!"&K$1&$V36, TRUE)} -> 4.9718197 | L36: {=INDIRECT("'※ 재무_세부시트'!"&L$1&$V36, TRUE)} -> 5.0249524 | M36: {=INDIRECT("'※ 재무_세부시트'!"&M$1&$V36, TRUE)} -> 9.4725025 | ... R36: {=INDIRECT("'※ 재무_세부시트'!"&R$1&$V36, TRUE)} -> 9.4725025 | U36: {=INDIRECT("'※ 재무_세부시트'!"&U$1&$V36, TRUE)} -> -1.1428195 | V36: 35
D37: 기타 | E37: B2B, 대형마트, 지원성 관리수수료, P3.0 등 | F37: {=INDIRECT("'※ 재무_세부시트'!"&F$1&$V37, TRUE)} -> 149.85056 | G37: {=INDIRECT("'※ 재무_세부시트'!"&G$1&$V37, TRUE)} -> 11.163948 | H37: {=INDIRECT("'※ 재무_세부시트'!"&H$1&$V37, TRUE)} -> 13.17639 | I37: {=INDIRECT("'※ 재무_세부시트'!"&I$1&$V37, TRUE)} -> 9.8586543 | J37: {=INDIRECT("'※ 재무_세부시트'!"&J$1&$V37, TRUE)} -> 19.145845 | K37: {=INDIRECT("'※ 재무_세부시트'!"&K$1&$V37, TRUE)} -> 9.4178594 | L37: {=INDIRECT("'※ 재무_세부시트'!"&L$1&$V37, TRUE)} -> 18.102218 | M37: {=INDIRECT("'※ 재무_세부시트'!"&M$1&$V37, TRUE)} -> 24.525262 | ... R37: {=INDIRECT("'※ 재무_세부시트'!"&R$1&$V37, TRUE)} -> 24.525262 | U37: {=INDIRECT("'※ 재무_세부시트'!"&U$1&$V37, TRUE)} -> 0.18492327 | V37: 36
C38: 기타수수료 | F38: {=INDIRECT("'※ 재무_세부시트'!"&F$1&$V38, TRUE)} -> 466.51983 | G38: {=INDIRECT("'※ 재무_세부시트'!"&G$1&$V38, TRUE)} -> 32.779204 | H38: {=INDIRECT("'※ 재무_세부시트'!"&H$1&$V38, TRUE)} -> 38.21154 | I38: {=INDIRECT("'※ 재무_세부시트'!"&I$1&$V38, TRUE)} -> 39.763803 | J38: {=INDIRECT("'※ 재무_세부시트'!"&J$1&$V38, TRUE)} -> 39.829534 | K38: {=INDIRECT("'※ 재무_세부시트'!"&K$1&$V38, TRUE)} -> 40.952531 | L38: {=INDIRECT("'※ 재무_세부시트'!"&L$1&$V38, TRUE)} -> 41.618138 | M38: {=INDIRECT("'※ 재무_세부시트'!"&M$1&$V38, TRUE)} -> 74.926283 | ... U38: {=INDIRECT("'※ 재무_세부시트'!"&U$1&$V38, TRUE)} -> 3.9355385 | V38: 37
C39: 수수료 항목 | D39: 도매위탁 | E39: 도매 도급수수료 | F39: {=INDIRECT("'※ 재무_세부시트'!"&F$1&$V39, TRUE)} -> 316.17347 | G39: {=INDIRECT("'※ 재무_세부시트'!"&G$1&$V39, TRUE)} -> 26.927905 | H39: {=INDIRECT("'※ 재무_세부시트'!"&H$1&$V39, TRUE)} -> 27.037246 | I39: {=INDIRECT("'※ 재무_세부시트'!"&I$1&$V39, TRUE)} -> 26.95 | J39: {=INDIRECT("'※ 재무_세부시트'!"&J$1&$V39, TRUE)} -> 25 | K39: {=INDIRECT("'※ 재무_세부시트'!"&K$1&$V39, TRUE)} -> 25 | L39: {=INDIRECT("'※ 재무_세부시트'!"&L$1&$V39, TRUE)} -> 25 | M39: {=INDIRECT("'※ 재무_세부시트'!"&M$1&$V39, TRUE)} -> 50 | ... U39: {=INDIRECT("'※ 재무_세부시트'!"&U$1&$V39, TRUE)} -> -3.9651514 | V39: 38
D40: KTAC 위탁 | E40: 아이폰 AW 업무위탁 | F40: {=INDIRECT("'※ 재무_세부시트'!"&F$1&$V40, TRUE)} -> 13.60989 | G40: {=INDIRECT("'※ 재무_세부시트'!"&G$1&$V40, TRUE)} -> 1.35002 | H40: {=INDIRECT("'※ 재무_세부시트'!"&H$1&$V40, TRUE)} -> 1.32668 | I40: {=INDIRECT("'※ 재무_세부시트'!"&I$1&$V40, TRUE)} -> 1.35615 | J40: {=INDIRECT("'※ 재무_세부시트'!"&J$1&$V40, TRUE)} -> 1.26417 | K40: {=INDIRECT("'※ 재무_세부시트'!"&K$1&$V40, TRUE)} -> 1.27146 | L40: {=INDIRECT("'※ 재무_세부시트'!"&L$1&$V40, TRUE)} -> 1.11978 | M40: {=INDIRECT("'※ 재무_세부시트'!"&M$1&$V40, TRUE)} -> 0.67008 | ... U40: {=INDIRECT("'※ 재무_세부시트'!"&U$1&$V40, TRUE)} -> -2.00662 | V40: 39
D41: KT닷컴 위탁 | E41: KT SHOP 도급수수료 | F41: {=INDIRECT("'※ 재무_세부시트'!"&F$1&$V41, TRUE)} -> 77.05255 | G41: {=INDIRECT("'※ 재무_세부시트'!"&G$1&$V41, TRUE)} -> 1.7813861 | H41: {=INDIRECT("'※ 재무_세부시트'!"&H$1&$V41, TRUE)} -> 6.49188 | I41: {=INDIRECT("'※ 재무_세부시트'!"&I$1&$V41, TRUE)} -> 6.49594 | J41: {=INDIRECT("'※ 재무_세부시트'!"&J$1&$V41, TRUE)} -> 6.9941842 | K41: {=INDIRECT("'※ 재무_세부시트'!"&K$1&$V41, TRUE)} -> 6.898 | L41: {=INDIRECT("'※ 재무_세부시트'!"&L$1&$V41, TRUE)} -> 6.89902 | M41: {=INDIRECT("'※ 재무_세부시트'!"&M$1&$V41, TRUE)} -> 15.12844 | ... U41: {=INDIRECT("'※ 재무_세부시트'!"&U$1&$V41, TRUE)} -> 6.8551739 | V41: 40
...

Sheet ※ 재무_세부시트
F1: E | R1: E | CR1: =SUBSTITUTE(ADDRESS(1,COLUMN(),4),"1","") -> CR | CS1: =SUBSTITUTE(ADDRESS(1,COLUMN(),4),"1","") -> CS | CT1: =SUBSTITUTE(ADDRESS(1,COLUMN(),4),"1","") -> CT | CU1: =SUBSTITUTE(ADDRESS(1,COLUMN(),4),"1","") -> CU | CV1: =SUBSTITUTE(ADDRESS(1,COLUMN(),4),"1","") -> CV | CW1: =SUBSTITUTE(ADDRESS(1,COLUMN(),4),"1","") -> CW | CX1: =SUBSTITUTE(ADDRESS(1,COLUMN(),4),"1","") -> CX
A2: □ 재무실적 | E2: ='0. 개요'!AE2 -> 46054 | F2: 2020.01 | G2: 2020.02 | H2: 2020.03 | I2: 2020.04 | J2: 2020.05 | K2: 2020.06 | L2: 2020.07 | M2: 2020.08 | N2: 2020.09 | O2: 2020.1 | P2: 2020.11 | Q2: 2020.12 | R2: 2021.01 | S2: 2021.02 | T2: 2021.03 | U2: 2021.04 | V2: 2021.05 | W2: 2021.06 | X2: 2021.07 | Y2: 2021.08 | Z2: 2021.09 | AA2: 2021.1 | AB2: 2021.11 | AC2: 2021.12 | AD2: 2022.01 | AE2: 2022.02 | AF2: 2022.03 | AG2: 2022.04 | AH2: 2022.05 | AI2: 2022.06 | AJ2: 2022.07 | AK2: 2022.08 | AL2: 2022.09 | AM2: 2022.1 | AN2: 2022.11 | AO2: 2022.12 | AQ2: 2023.01 | AR2: 2023.02 | AS2: 2023.03 | AT2: 2023.04 | AU2: 2023.05 | AV2: 2023.06 | AW2: 2023.07 | AX2: 2023.08 | AY2: 2023.09 | AZ2: 2023.1 | BA2: 2023.11 | BB2: 2023.12 | BD2: 2024.01 | BE2: 2024.02 | BF2: 2024.03 | BG2: 2024.04 | BH2: 2024.05 | BI2: 2024.06 | BJ2: 2024.07 | BK2: 2024.08 | BL2: 2024.09 | BM2: 2024.1 | BN2: 2024.11 | BO2: 2024.12 | DA2: 1.001 | DB2: 2.001 | DC2: 3.001 | DD2: 4.001 | DE2: 5.001 | DF2: 6.001 | DG2: 7.001 | DH2: 8.001 | DI2: 9.001 | DJ2: 10.001 | DK2: 11.001 | DL2: 12.001
A3: (단위 : 억원) | E3: ※ 내부 도전목표 | F3: 2020년 | M3: =M5-M7-M54 -> 20.234601 | R3: 2021년 | Y3: =Y5-Y7-Y54 -> 7.4974503 | AD3: 2022년 | AK3: =AK5-AK7-AK54 -> 10.433726 | AQ3: 2023년 | BD3: 2024년 | BQ3: 2025년 | CD3: 2026년 | CU3: ="연간누적실적(~"&MONTH(E2)&"월)" -> 연간누적실적(~2월)
A4: 구분 | E4: 설명 | F4: '20.1월 | G4: '20.2월 | H4: '20.3월 | I4: '20.4월 | J4: '20.5월 | K4: '20.6월 | L4: '20.7월 | M4: '20.8월 | N4: '20.9월 | O4: '20.10월 | P4: '20.11월 | Q4: '20.12월 | R4: '21.1월 | S4: '21.2월 | T4: '21.3월 | U4: '21.4월 | V4: '21.5월 | W4: '21.6월 | X4: '21.7월 | Y4: '21.8월 | Z4: '21.9월 | AA4: '21.10월 | AB4: '21.11월 | AC4: '21.12월 | AD4: '22.1월 | AE4: '22.2월 | AF4: '22.3월 | AG4: '22.4월 | AH4: '22.5월 | AI4: '22.6월 | AJ4: '22.7월 | AK4: '22.8월 | AL4: '22.9월 | AM4: '22.10월 | AN4: '22.11월 | AO4: '22.12월 | AP4: 계 | AQ4: 23.1월 | AR4: 23.2월 | AS4: 23.3월 | AT4: 23.4월 | AU4: 23.5월 | AV4: 23.6월 | AW4: 23.7월 | AX4: 23.8월 | AY4: 23.9월 | AZ4: 23.10월 | BA4: 23.11월 | BB4: 23.12월 | BC4: 계 | BD4: '24.1월 | BE4: '24.2월 | BF4: 24.3월 | BG4: '24.4월 | BH4: '24.5월 | BI4: '24.6월 | BJ4: '24.7월 | BK4: '24.8월 | BL4: '24.9월 | BM4: '24.10월 | BN4: '24.11월 | BO4: '24.12월 | BP4: 계 | BQ4: '25.1월 | BR4: '25.2월 | BS4: '25.3월 | BT4: '25.4월 | BU4: '25.5월 | BV4: '25.6월 | BW4: '25.7월 | BX4: '25.8월 | BY4: '25.9월 | BZ4: '25.10월 | CA4: '25.11월 | CB4: '25.12월 | CC4: 계 | CD4: '26.1월 | CE4: '26.2월 | CF4: '26.3월 | CG4: '26.4월 | CH4: '26.5월 | CI4: '26.6월 | CJ4: '26.7월 | CK4: '26.8월 | CL4: '26.9월 | CM4: '26.10월 | CN4: '26.11월 | CO4: '26.12월 | CP4: 목표대비 | CQ4: 달성률 | CR4: 전월대비 | CS4: 전년 동월대비 | CT4: 전작 출시대비 | CU4: 누적 | CV4: 목표대비 | CW4: 달성률 | CX4: 전년 동기대비 | DA4: '26.1월 | DB4: '26.2월 | DC4: '26.3월 | DD4: '26.4월 | DE4: '26.5월 | DF4: '26.6월 | DG4: '26.7월 | DH4: '26.8월 | DI4: '26.9월 | DJ4: '26.10월 | DK4: '26.11월 | DL4: '26.12월 | DM4: 계
A5: 총매출 (ⓐ+ⓑ+ⓒ+ⓓ) | F5: 569.51147 | G5: 578.34212 | H5: 568.02299 | I5: 502.95302 | J5: 524.24927 | K5: 452.26849 | L5: 441.22264 | M5: 662.73824 | N5: 521.37494 | O5: 575.08277 | P5: 654.55505 | Q5: 561.64881 | R5: 567.26062 | S5: 506.97307 | T5: 509.6057 | U5: 534.82581 | V5: 511.04063 | W5: 530.63334 | X5: 495.89082 | Y5: 721.12801 | Z5: 658.38127 | AA5: 804.74588 | AB5: 644.2723 | AC5: 616.92996 | AD5: =AD6+AD12+AD49 -> 465.97 | AE5: =AE6+AE12+AE49 -> 686.7605 | AF5: =AF6+AF12+AF49 -> 518.85 | AG5: =AG6+AG12+AG49 -> 515.35 | AH5: =AH6+AH12+AH49 -> 562.35 | AI5: =AI6+AI12+AI49 -> 609.07305 | AJ5: 486.34172 | AK5: 764.8615 | AL5: 529.65776 | AM5: 958.54831 | AN5: 582.43953 | AO5: 605.0712 | AP5: =SUM(AD5:AO5) -> 7285.2736 | AQ5: 474.37248 | AR5: 736.97131 | AS5: 520.49606 | AT5: 489.87118 | AU5: 510.89928 | AV5: 472.27082 | AW5: 412.06067 | AX5: 845.34421 | AY5: 469.75417 | AZ5: 1016.6929 | BA5: 514.05647 | BB5: 488.55515 | BC5: 6951.3447 | BD5: =BD6+BD12+BD49 -> 1190.058 | BE5: =BE6+BE12+BE49 -> 614.86194 | BF5: =BF6+BF12+BF49 -> 557.68208 | BG5: =BG6+BG12+BG49 -> 500.51677 | BH5: =BH6+BH12+BH49 -> 429.9683 | BI5: =BI6+BI12+BI49 -> 619.57999 | BJ5: =BJ6+BJ12+BJ49 -> 762.35506 | BK5: 568.02692 | BL5: 936.12682 | BM5: 881.98863 | BN5: 494.88055 | BO5: 517.02606 | BP5: 8073.0711 | BQ5: =BQ6+BQ12+BQ49 -> 560.63833 | BR5: =BR6+BR12+BR49 -> 1003.2939 | BS5: =BS6+BS12+BS49 -> 569.23055 | BT5: =BT6+BT12+BT49 -> 449.51814 | BU5: =BU6+BU12+BU49 -> 517.36254 | BV5: =BV6+BV12+BV49 -> 544.95947 | BW5: =BW6+BW12+BW49 -> 810.20838 | BX5: =BX6+BX12+BX49 -> 537.55465 | ... CB5: =CB6+CB12+CB49 -> 507.16995 | CC5: =SUM(BQ5:CB5) -> 7534.581 | CD5: =CD6+CD12+CD49 -> 776.64177 | CE5: =CE6+CE12+CE49 -> 490.15396 | CP5: =HLOOKUP($E$2,$BQ$2:$CB$530,ROW()-1,0)-HLOOKUP($E$2,$DA$2:$DL$437,ROW()-1,0) -> #N/A | CQ5: =IFERROR(HLOOKUP($E$2,$BQ$2:$CB$530,ROW()-1,0)/HLOOKUP($E$2,$DA$2:$DL$437,ROW()-1,0),0) -> 0 | CR5: =CE5-CD5 -> -286.4878 | CS5: =CE5-BR5 -> -513.13996 | CU5: =SUM(CD5:CO5) -> 1266.7957 | CV5: =CU5-SUM(DA5:DB5) -> 1266.7957 | CW5: =IFERROR(CU5/SUM(DA5:DB5),0) -> 0 | CX5: =SUM(CD5:CE5)-SUM(BQ5:BR5) -> -297.13652 | CZ5: =A5 -> 총매출 (ⓐ+ⓑ+ⓒ+ⓓ) | DM5: =SUM(DA5:DL5) -> 0
A6: 상품매출 (ⓐ+ⓓ) | F6: 425.1258 | G6: 435.59137 | H6: 417.06116 | I6: 362.0861 | J6: 376.76339 | K6: 311.12636 | L6: 298.44903 | M6: 511.91695 | N6: 377.02539 | O6: 417.6057 | P6: 478.98465 | Q6: 421.78799 | R6: 427.30241 | S6: 359.95052 | T6: 373.13112 | U6: 392.55809 | V6: 350.17415 | W6: 355.84174 | X6: 327.1894 | Y6: 533.93235 | Z6: 487.44124 | AA6: 619.26929 | AB6: 478.3939 | AC6: 371.54032 | AD6: =AD11+AD52 -> 314.07 | AE6: =AE11+AE52 -> 510.5 | AF6: =AF11+AF52 -> 363.69 | AG6: =AG11+AG52 -> 337.67 | AH6: =AH11+AH52 -> 367.09 | AI6: =AI11+AI52 -> 398.52305 | AJ6: 292.67989 | AK6: 544.67727 | AL6: 342.49629 | AM6: 769.85844 | AN6: 414.74087 | AO6: 321.00398 | AQ6: 326.19489 | AR6: 526.58673 | AS6: 341.83856 | AT6: 294.56878 | AU6: 312.07731 | AV6: 247.27282 | AW6: 221.5312 | AX6: 575.99764 | AY6: 273.79615 | AZ6: 776.33182 | BA6: 344.11767 | BB6: 287.62393 | BC6: 4527.9375 | BD6: =BD11+BD52 -> 940.06422 | BE6: =BE11+BE52 -> 427.55354 | BF6: =BF11+BF52 -> 367.05735 | BG6: =BG11+BG52 -> 287.88902 | BH6: =BH11+BH52 -> 238.00012 | BI6: =BI11+BI52 -> 431.33398 | BJ6: =BJ11+BJ52 -> 492.63717 | BK6: =BK11+BK52 -> 361.22709 | ... BN6: =BN11+BN52 -> 285.92329 | BO6: 290.83169 | BP6: 5452.5105 | BQ6: =BQ11+BQ52 -> 377.4824 | BR6: =BR11+BR52 -> 737.1983 | BS6: =BS11+BS52 -> 368.49675 | BT6: =BT11+BT52 -> 243.45807 | BU6: =BU11+BU52 -> 287.03542 | BV6: =BV11+BV52 -> 319.55447 | BW6: =BW11+BW52 -> 493.41569 | BX6: =BX11+BX52 -> 313.17966 | ... CB6: =CB11+CB52 -> 222.84258 | CC6: =SUM(BQ6:CB6) -> 4676.9607 | CD6: =CD11+CD52 -> 508.33631 | CE6: =CE11+CE52 -> 288.02521 | CP6: =HLOOKUP($E$2,$BQ$2:$CB$530,ROW()-1,0)-HLOOKUP($E$2,$DA$2:$DL$437,ROW()-1,0) -> #N/A | CQ6: =IFERROR(HLOOKUP($E$2,$BQ$2:$CB$530,ROW()-1,0)/HLOOKUP($E$2,$DA$2:$DL$437,ROW()-1,0),0) -> 0 | CR6: =CE6-CD6 -> -220.3111 | CS6: =CE6-BR6 -> -449.17309 | CU6: =SUM(CD6:CO6) -> 796.36152 | CV6: =CU6-SUM(DA6:DB6) -> 796.36152 | CW6: =IFERROR(CU6/SUM(DA6:DB6),0) -> 0 | CX6: =SUM(CD6:CE6)-SUM(BQ6:BR6) -> -318.31918 | CZ6: =A6 -> 상품매출 (ⓐ+ⓓ) | DM6: =SUM(DA6:DL6) -> 0
A7: 상품원가 | F7: 431.05112 | G7: 439.98351 | H7: 418.06972 | I7: 355.84579 | J7: 376.48167 | K7: 305.23117 | L7: 297.5759 | M7: 510.57504 | N7: 381.12291 | O7: 415.98218 | P7: 486.8089 | Q7: 421.27194 | R7: 430.318 | S7: 362.04686 | T7: 366.78754 | U7: 397.33485 | V7: 361.3201 | W7: 374.57079 | X7: 345.47228 | Y7: 572.08191 | Z7: 500.30267 | AA7: 644.31456 | AB7: 489.556 | AC7: 403.14611 | AD7: 335.93 | AE7: 528.1 | AF7: 336.8 | AG7: 350.28 | AH7: 381.14 | AI7: 425.59492 | AJ7: 309.76084 | AK7: 583.86101 | AL7: 340.89587 | AM7: 777.74195 | AN7: 419.88816 | AO7: 321.84356 | AQ7: 332.61489 | AR7: 563.94445 | AS7: 347.8352 | AT7: 318.36152 | AU7: 338.16961 | AV7: 266.59199 | AW7: 230.31367 | AX7: 636.29756 | AY7: 264.79659 | AZ7: 768.34303 | BA7: 341.94122 | BB7: 284.83683 | BC7: 4694.0465 | BD7: 998.0768 | BE7: 439.12202 | BF7: 382.102 | BG7: 315.69318 | BH7: 265.66272 | BI7: 461.67626 | BJ7: 564.07347 | BK7: 389.93011 | BL7: 703.64603 | BM7: 663.13773 | BN7: 316.72315 | BO7: 325.68991 | BP7: 5825.5334 | BQ7: 388.7483 | BR7: 790.57614 | BS7: 385.18887 | BT7: 256.63171 | BU7: 307.72262 | BV7: 324.79942 | BW7: 562.04739 | BX7: 357.89969 | BY7: 628.35759 | BZ7: 396.72068 | CA7: 359.6247 | CB7: 254.39444 | CC7: =SUM(BQ7:CB7) -> 5012.7115 | CD7: 565.01271 | CE7: 313.4945 | CP7: =HLOOKUP($E$2,$BQ$2:$CB$530,ROW()-1,0)-HLOOKUP($E$2,$DA$2:$DL$437,ROW()-1,0) -> #N/A | CQ7: =IFERROR(HLOOKUP($E$2,$BQ$2:$CB$530,ROW()-1,0)/HLOOKUP($E$2,$DA$2:$DL$437,ROW()-1,0),0) -> 0 | CR7: =CE7-CD7 -> -251.51821 | CS7: =CE7-BR7 -> -477.08163 | CU7: =SUM(CD7:CO7) -> 878.50721 | CV7: =CU7-SUM(DA7:DB7) -> 878.50721 | CW7: =IFERROR(CU7/SUM(DA7:DB7),0) -> 0 | CX7: =SUM(CD7:CE7)-SUM(BQ7:BR7) -> -300.81723 | CZ7: =A7 -> 상품원가 | DM7: =SUM(DA7:DL7) -> 0
A8: 상품이익 | F8: =(F6-F7) -> -5.9253217 | G8: =(G6-G7) -> -4.3921413 | H8: =(H6-H7) -> -1.0085613 | I8: =(I6-I7) -> 6.2403063 | J8: =(J6-J7) -> 0.28171238 | K8: =(K6-K7) -> 5.8951933 | L8: =(L6-L7) -> 0.87313211 | M8: =(M6-M7) -> 1.3419101 | ... Q8: =(Q6-Q7) -> 0.51604462 | R8: -3.0155906 | S8: -2.0963358 | T8: 6.3435833 | U8: -4.7767639 | V8: -11.145956 | W8: -18.729043 | X8: -18.282875 | Y8: -38.149559 | Z8: -12.861424 | AA8: -25.045272 | AB8: -11.1621 | AC8: -31.605795 | AD8: =AD6-AD7 -> -21.86 | AE8: =AE6-AE7 -> -17.6 | AF8: =AF6-AF7 -> 26.89 | AG8: =AG6-AG7 -> -12.61 | AH8: =AH6-AH7 -> -14.05 | AI8: =AI6-AI7 -> -27.071866 | AJ8: -17.080956 | AK8: -39.183743 | AL8: 1.6004203 | AM8: -7.8835159 | AN8: -5.1472846 | AO8: -0.8395823 | AQ8: -6.419994 | AR8: -37.357717 | AS8: -5.9966427 | AT8: -23.792732 | AU8: -26.092303 | AV8: -19.319165 | AW8: -8.782463 | AX8: -60.299919 | AY8: 8.9995535 | AZ8: 7.988791 | BA8: 2.1764484 | BB8: 2.7870985 | BC8: -166.10904 | BD8: =BD6-BD7 -> -58.012584 | BE8: =BE6-BE7 -> -11.568477 | BF8: =BF6-BF7 -> -15.044648 | BG8: =BG6-BG7 -> -27.804163 | BH8: =BH6-BH7 -> -27.662603 | BI8: =BI6-BI7 -> -30.342279 | BJ8: =BJ6-BJ7 -> -71.436297 | BK8: =BK6-BK7 -> -28.703017 | ... BO8: =BO6-BO7 -> -34.858223 | BP8: -373.02286 | BQ8: =BQ6-BQ7 -> -11.265901 | BR8: =BR6-BR7 -> -53.377835 | BS8: -16.692117 | BT8: -13.173643 | BU8: -20.6872 | BV8: -5.2449434 | BW8: -68.631704 | BX8: -44.720026 | BY8: -16.504638 | BZ8: -30.998463 | CA8: -22.902526 | CB8: -31.551856 | CC8: =SUM(BQ8:CB8) -> -335.75085 | CD8: -56.676402 | CE8: -25.46929 | CP8: =HLOOKUP($E$2,$BQ$2:$CB$530,ROW()-1,0)-HLOOKUP($E$2,$DA$2:$DL$437,ROW()-1,0) -> #N/A | CQ8: - | CR8: =CE8-CD8 -> 31.207112 | CS8: =CE8-BR8 -> 27.908545 | CU8: =SUM(CD8:CO8) -> -82.145691 | CV8: =CU8-SUM(DA8:DB8) -> -82.145691 | CW8: - | CX8: =SUM(CD8:CE8)-SUM(BQ8:BR8) -> -17.501956 | CZ8: =A8 -> 상품이익 | DM8: =SUM(DA8:DL8) -> 0
B9: * 프리할부 | R9: 0.2204745 | S9: 1.1927519 | T9: 2.9505761 | U9: 3.4128351 | V9: 2.7226737 | W9: 9.8159841 | X9: 18.61316 | Y9: 33.8014 | Z9: 13.003586 | AA9: 12.992893 | AB9: 10.694398 | AC9: 10.168739 | AD9: 10.513296 | AE9: 19.256461 | AF9: 11.210794 | AG9: 11.913514 | AH9: 11.241397 | AI9: 23.006637 | AJ9: 8.7868278 | AK9: 27.523995 | AL9: 11.145711 | AM9: 12.810581 | AN9: 9.0803425 | AO9: 8.0588852 | AQ9: 8.9098142 | AR9: 21.689249 | AS9: 14.507444 | AT9: 17.838919 | AU9: 17.41659 | AV9: 16.89778 | AW9: 11.35646 | AX9: 35.958989 | AY9: 8.879484 | AZ9: 21.659157 | BA9: 9.1784308 | BB9: 5.9321402 | BC9: 190.22446 | BD9: 46.830659 | BE9: 28.690831 | BF9: 23.280654 | BG9: 21.779793 | BH9: 23.41266 | BI9: 25.559514 | BJ9: 67.529861 | BK9: 26.370876 | BL9: 40.438865 | BM9: 18.069985 | BN9: 17.555633 | BO9: 13.641782 | BP9: 353.16111 | BQ9: 15.730997 | BR9: 40.752403 | CC9: =SUM(BQ9:CB9) -> 56.4834 | CP9: =HLOOKUP($E$2,$BQ$2:$CB$530,ROW()-1,0)-HLOOKUP($E$2,$DA$2:$DL$437,ROW()-1,0) -> #N/A | CQ9: =IFERROR(2-ABS(HLOOKUP($E$2,$BQ$2:$CB$530,ROW()-1,0)/HLOOKUP($E$2,$DA$2:$DL$437,ROW()-1,0)),0) -> 0 | CR9: =CE9-CD9 -> 0 | CS9: =CE9-BR9 -> -40.752403 | CU9: =SUM(CD9:CO9) -> 0 | CV9: =CU9-SUM(DA9:DB9) -> 0 | CW9: =IFERROR(2-ABS(CU9/SUM(DA9:DB9)),0) -> 0 | CX9: =SUM(CD9:CE9)-SUM(BQ9:BR9) -> -56.4834 | CZ9: =B9 -> * 프리할부 | DM9: =SUM(DA9:DL9) -> 0
A10: 통신매출 | F10: =F11+F12 -> 569.51147 | G10: =G11+G12 -> 578.34212 | H10: =H11+H12 -> 568.02299 | I10: =I11+I12 -> 502.95302 | J10: =J11+J12 -> 524.24927 | K10: =K11+K12 -> 452.26849 | L10: =L11+L12 -> 441.22264 | M10: =M11+M12 -> 662.73824 | ... AC10: =AC11+AC12 -> 616.92996 | AQ10: =AQ11+AQ12 -> 455.44412 | AR10: =AR11+AR12 -> 716.63619 | AS10: =AW11+AW12 -> 405.6814 | AT10: =AT11+AT12 -> 465.41111 | AU10: =AU11+AU12 -> 466.02965 | AV10: =AV11+AV12 -> 463.61065 | AW10: =AW11+AW12 -> 405.6814 | AX10: =AX11+AX12 -> 822.26186 | AY10: =AY11+AY12 -> 434.32383 | AZ10: =AZ11+AZ12 -> 986.75108 | BA10: =BA11+BA12 -> 503.84647 | BB10: =BB11+BB12 -> 449.86678 | BC10: =SUM(AQ10:BB10) -> 6575.5445 | BD10: =BD11+BD12 -> 1186.5926 | BE10: =BE11+BE12 -> 597.79148 | BF10: =BF11+BF12 -> 529.86588 | BG10: =BG11+BG12 -> 441.67583 | BH10: =BH11+BH12 -> 402.75332 | BI10: =BI11+BI12 -> 611.33347 | BJ10: =BJ11+BJ12 -> 748.57846 | BK10: =BK11+BK12 -> 515.44757 | ... BO10: =BO11+BO12 -> 489.19614 | BP10: 7673.4989 | BQ10: =BQ11+BQ12 -> 533.56526 | BR10: =BR11+BR12 -> 937.0369 | BS10: =BS11+BS12 -> 520.82451 | BT10: =BT11+BT12 -> 413.50723 | BU10: =BU11+BU12 -> 474.81409 | BV10: =BV11+BV12 -> 497.40316 | BW10: =BW11+BW12 -> 753.50974 | BX10: =BX11+BX12 -> 479.35549 | ... CB10: =CB11+CB12 -> 490.8168 | CC10: =SUM(BQ10:CB10) -> 6977.9968 | CD10: =CD11+CD12 -> 761.90834 | CE10: =CE11+CE12 -> 462.24415 | CP10: =HLOOKUP($E$2,$BQ$2:$CB$530,ROW()-1,0)-HLOOKUP($E$2,$DA$2:$DL$437,ROW()-1,0) -> #N/A | CQ10: =IFERROR(HLOOKUP($E$2,$BQ$2:$CB$530,ROW()-1,0)/HLOOKUP($E$2,$DA$2:$DL$437,ROW()-1,0),0) -> 0 | CR10: =CE10-CD10 -> -299.6642 | CS10: =CE10-BR10 -> -474.79275 | CU10: =SUM(CD10:CO10) -> 1224.1525 | CV10: =CU10-SUM(DA10:DB10) -> 1224.1525 | CW10: =IFERROR(CU10/SUM(DA10:DB10),0) -> 0 | CX10: =SUM(CD10:CE10)-SUM(BQ10:BR10) -> -246.44967 | CZ10: =A10 -> 통신매출 | DM10: =DM11+DM12 -> 0
B11: 상품매출(통신) ⓐ | F11: 425.1258 | G11: =G6 -> 435.59137 | H11: =H6 -> 417.06116 | I11: =I6 -> 362.0861 | J11: =J6 -> 376.76339 | K11: =K6 -> 311.12636 | L11: =L6 -> 298.44903 | M11: =M6 -> 511.91695 | N11: =N6 -> 377.02539 | ... Q11: =Q6 -> 421.78799 | R11: 427.30241 | S11: 359.95052 | T11: 373.13112 | U11: 392.55809 | V11: 350.17415 | W11: 355.84174 | X11: 327.1894 | Y11: 533.93235 | Z11: 487.44124 | AA11: 619.26929 | AB11: 478.3939 | AC11: 371.54032 | AD11: 314.07 | AE11: 510.5 | AF11: 363.69 | AG11: 337.67 | AH11: 367.09 | AI11: 398.52305 | AJ11: 292.67989 | AK11: 544.67727 | AL11: 342.49629 | AM11: 769.85844 | AN11: 414.74087 | AO11: 321.00398 | AQ11: 307.5619 | AR11: 506.3474 | AS11: 335.51971 | AT11: 270.10871 | AU11: 267.22187 | AV11: 238.84648 | AW11: 215.1817 | AX11: 553.17258 | AY11: 238.47596 | AZ11: 746.45886 | BA11: 333.94233 | BB11: 251.21295 | BC11: 4264.0504 | BD11: 937.30233 | BE11: 412.93291 | BF11: 340.37765 | BG11: 236.73679 | BH11: 212.96512 | BI11: =42433.744472/100 -> 424.33744 | BJ11: 480.94917 | BK11: 311.64623 | BL11: 614.09557 | BM11: 599.40744 | BN11: 263.86619 | BO11: 268.77934 | BP11: 5103.3962 | BQ11: 355.07525 | BR11: 679.23028 | BS11: 321.5338 | BT11: 213.07458 | BU11: 246.36239 | BV11: 274.80847 | BW11: 441.47967 | BX11: 256.74805 | BY11: 559.57756 | BZ11: 324.9823 | CA11: 284.83314 | CB11: 209.09681 | CC11: =SUM(BQ11:CB11) -> 4166.8023 | CD11: 497.57642 | CE11: 261.19275 | CP11: =HLOOKUP($E$2,$BQ$2:$CB$530,ROW()-1,0)-HLOOKUP($E$2,$DA$2:$DL$437,ROW()-1,0) -> #N/A | CQ11: =IFERROR(HLOOKUP($E$2,$BQ$2:$CB$530,ROW()-1,0)/HLOOKUP($E$2,$DA$2:$DL$437,ROW()-1,0),0) -> 0 | CR11: =CE11-CD11 -> -236.38367 | CS11: =CE11-BR11 -> -418.03754 | CU11: =SUM(CD11:CO11) -> 758.76916 | CV11: =CU11-SUM(DA11:DB11) -> 758.76916 | CW11: =IFERROR(CU11/SUM(DA11:DB11),0) -> 0 | CX11: =SUM(CD11:CE11)-SUM(BQ11:BR11) -> -275.53637 | CZ11: =B11 -> 상품매출(통신) ⓐ | DM11: =SUM(DA11:DL11) -> 0
B12: 수수료매출(통신) ⓑ | F12: 144.38567 | G12: 142.75075 | H12: 150.96183 | I12: 140.86692 | J12: 147.48588 | K12: 141.14213 | L12: 142.77361 | M12: 150.82129 | N12: 144.34955 | O12: 157.47707 | P12: 175.5704 | Q12: 139.86082 | R12: 139.95821 | S12: 147.02255 | T12: 136.47458 | U12: 142.26772 | V12: 160.86648 | W12: 174.7916 | X12: 168.70142 | Y12: 187.19565 | Z12: 170.94003 | AA12: 185.47659 | AB12: 165.8784 | AC12: 245.38964 | AD12: 151.9 | AE12: 176.2605 | AF12: 155.16 | AG12: 177.68 | AH12: 195.26 | AI12: 210.55 | AJ12: 193.66183 | AK12: 220.18424 | AL12: 187.16146 | AM12: 188.68793 | AN12: 167.69945 | AO12: 284.06722 | AQ12: 147.88222 | AR12: 210.2888 | AS12: 178.60839 | AT12: 195.3024 | AU12: 198.80779 | AV12: 224.76417 | AW12: 190.4997 | AX12: 269.08928 | AY12: 195.84787 | AZ12: 240.29222 | BA12: 169.90414 | BB12: 198.65383 | BC12: 2419.9408 | BD12: =BD13+BD21+BD37 -> 249.29026 | BE12: =BE13+BE21+BE37 -> 184.85857 | BF12: =BF13+BF21+BF37 -> 189.48823 | BG12: =BG13+BG21+BG37 -> 204.93904 | BH12: =BH13+BH21+BH37 -> 189.7882 | BI12: =BI13+BI21+BI37 -> 186.99602 | BJ12: =BJ13+BJ21+BJ37 -> 267.6293 | BK12: 203.80134 | BL12: 263.40403 | BM12: 215.45701 | BN12: 194.03395 | BO12: 220.4168 | BP12: 2570.1027 | BQ12: =BQ13+BQ21+BQ37 -> 178.49001 | BR12: =BR13+BR21+BR37 -> 257.80661 | BS12: =BS13+BS21+BS37 -> 199.29071 | BT12: =BT13+BT21+BT37 -> 200.43265 | BU12: =BU13+BU21+BU37 -> 228.4517 | BV12: =BV13+BV21+BV37 -> 222.5947 | BW12: =BW13+BW21+BW37 -> 312.03007 | BX12: =BX13+BX21+BX37 -> 222.60744 | ... CB12: =CB13+CB21+CB37 -> 281.71999 | CC12: =SUM(BQ12:CB12) -> 2811.1945 | CD12: =CD13+CD21+CD37 -> 264.33193 | CE12: =CE13+CE21+CE37 -> 201.0514 | CP12: =HLOOKUP($E$2,$BQ$2:$CB$530,ROW()-1,0)-HLOOKUP($E$2,$DA$2:$DL$437,ROW()-1,0) -> #N/A | CQ12: =IFERROR(HLOOKUP($E$2,$BQ$2:$CB$530,ROW()-1,0)/HLOOKUP($E$2,$DA$2:$DL$437,ROW()-1,0),0) -> 0 | CR12: =CE12-CD12 -> -63.280527 | CS12: =CE12-BR12 -> -56.755214 | CU12: =SUM(CD12:CO12) -> 465.38333 | CV12: =CU12-SUM(DA12:DB12) -> 465.38333 | CW12: =IFERROR(CU12/SUM(DA12:DB12),0) -> 0 | CX12: =SUM(CD12:CE12)-SUM(BQ12:BR12) -> 29.0867 | CZ12: =B12 -> 수수료매출(통신) ⓑ | DM12: =SUM(DA12:DL12) -> 0
C13: 정책수수료 | F13: =F14+F15 -> 66.505846 | G13: =G14+G15 -> 61.65532 | H13: =H14+H15 -> 68.598156 | I13: =I14+I15 -> 62.736616 | J13: =J14+J15 -> 71.736811 | K13: =K14+K15 -> 67.407589 | L13: =L14+L15 -> 66.153399 | M13: =M14+M15 -> 73.141149 | ... Q13: =Q14+Q15 -> 65.332407 | R13: 67.759317 | S13: 70.007579 | T13: 62.487498 | U13: 56.436671 | V13: 82.521391 | W13: 96.041539 | X13: 88.505993 | Y13: 106.62665 | Z13: 91.159278 | AA13: 100.95803 | AB13: 83.633351 | AC13: 162.32011 | AD13: =AD14+AD15 -> 67.67705 | AE13: =AE14+AE15 -> 93.341094 | AF13: =AF14+AF15 -> 66.686359 | AG13: =AG14+AG15 -> 96.55179 | AH13: =AH14+AH15 -> 102.01928 | AI13: =AI14+AI15 -> 107.7027 | AJ13: 104.29413 | AK13: 128.80382 | AL13: 91.154754 | AM13: 108.8466 | AN13: 75.910748 | AO13: 198.0971 | AQ13: 39.929752 | AR13: 126.18733 | AS13: 78.487283 | AT13: 106.54675 | AU13: 107.44778 | AV13: 126.97077 | AW13: 94.720605 | AX13: 176.59734 | AY13: 99.013855 | AZ13: 146.00524 | BA13: 80.487954 | BB13: 105.05089 | BC13: 1287.4455 | BD13: =BD14+BD15 -> 149.15128 | BE13: =BE14+BE15 -> 88.394005 | BF13: =BF14+BF15 -> 98.747063 | BG13: =BG14+BG15 -> 104.10232 | BH13: =BH14+BH15 -> 98.473285 | BI13: =BI14+BI15 -> 90.230886 | BJ13: =BJ14+BJ15 -> 167.22273 | BK13: =BK14+BK15 -> 100.31821 | ... BN13: =BN14+BN15 -> 91.538161 | BO13: 113.04965 | BP13: 1379.1252 | BQ13: =BQ14+BQ15 -> 95.784424 | BR13: =BR14+BR15 -> 166.62482 | BS13: =BS14+BS15 -> 110.26219 | BT13: =BT14+BT15 -> 103.99978 | BU13: =BU14+BU15 -> 141.27507 | BV13: =BV14+BV15 -> 121.71604 | BW13: =BW14+BW15 -> 222.07762 | BX13: =BX14+BX15 -> 134.99656 | ... CB13: =CB14+CB15 -> 183.7316 | CC13: =SUM(BQ13:CB13) -> 1729.0321 | CD13: =CD14+CD15 -> 177.21647 | CE13: =CE14+CE15 -> 114.39849 | CP13: =HLOOKUP($E$2,$BQ$2:$CB$530,ROW()-1,0)-HLOOKUP($E$2,$DA$2:$DL$437,ROW()-1,0) -> #N/A | CQ13: =IFERROR(HLOOKUP($E$2,$BQ$2:$CB$530,ROW()-1,0)/HLOOKUP($E$2,$DA$2:$DL$437,ROW()-1,0),0) -> 0 | CR13: =CE13-CD13 -> -62.817979 | CS13: =CE13-BR13 -> -52.226327 | CU13: =SUM(CD13:CO13) -> 291.61496 | CV13: =CU13-SUM(DA13:DB13) -> 291.61496 | CW13: =IFERROR(CU13/SUM(DA13:DB13),0) -> 0 | CX13: =SUM(CD13:CE13)-SUM(BQ13:BR13) -> 29.205717 | CZ13: =C13 -> 정책수수료 | DM13: =SUM(DA13:DL13) -> 0
C14: 유무선 | D14: 무선 | E14: 무선 판매 수수료 | F14: 62.75219 | G14: 62.168843 | H14: 60.703696 | I14: 57.652085 | J14: 71.994799 | K14: 63.717377 | L14: 62.150368 | M14: 68.340835 | N14: 67.181898 | O14: 77.373199 | P14: 100.84694 | Q14: 62.70447 | R14: 61.290173 | S14: 69.716658 | T14: 66.155376 | U14: 53.694534 | V14: 79.413041 | W14: 92.119046 | X14: 86.365993 | Y14: 105.34176 | Z14: 86.918445 | AA14: 95.634805 | AB14: 78.468243 | AC14: 160.86679 | AD14: 63.368882 | AE14: 89.881481 | AF14: 68.727471 | AG14: 91.613518 | AH14: 99.935672 | AI14: 107.0345 | AJ14: 105.11114 | AK14: 123.94395 | AL14: 78.88936 | AM14: 103.79931 | AN14: 76.776728 | AO14: 201.97585 | AQ14: 39.60789 | AR14: 121.51036 | AS14: 77.057831 | AT14: 102.43476 | AU14: 104.80835 | AV14: 127.02526 | AW14: 97.74771 | AX14: 170.64927 | AY14: 104.0049 | AZ14: 145.86148 | BA14: 81.000903 | BB14: 105.20129 | BC14: 1276.91 | BD14: =(14291.505822/100)-BD50 -> 142.52133 | BE14: =(9284.452229/100)-BE50 -> 90.686996 | BF14: =(8770.307297/100)-BF50 -> 87.08772 | BG14: =(9702.226127/100)-BG50 -> 92.756791 | BH14: =86.95162969-BH50 -> 85.287552 | BI14: =77.96328659-BI50 -> 77.151313 | BJ14: =157.8282656-BJ50 -> 156.24824 | BK14: 97.709643 | BL14: 143.05632 | BM14: =120.75488342-BM50 -> 117.21302 | BN14: =100.21921748-BN50 -> 85.758136 | BO14: 106.62769 | BP14: 1282.1047 | BQ14: =94.15998888-BQ50 -> 90.1286 | BR14: =151.65931031-BR50 -> 143.86298 | BS14: =102.7766701-BS50 -> 101.90002 | BT14: =96.94536196-BT50 -> 94.597902 | BU14: =124.46163737-BU50 -> 123.0866 | BV14: =124.27085998-BV50 -> 121.90912 | BW14: =205.26703566-BW50 -> 202.70676 | BX14: =131.93518587-BX50 -> 131.07891 | BY14: =174.5332867-BY50 -> 170.82372 | BZ14: =119.42022718-BZ50 -> 115.48542 | CA14: =(133.48945797)-CA50 -> 131.92252 | CB14: =(16319.165186/100)-CB50 -> 161.46235 | CC14: =SUM(BQ14:CB14) -> 1588.9649 | CD14: =161.33931091-CD50 -> 158.6071 | CE14: =98.35605829-CE50 -> 98.10253 | CP14: =HLOOKUP($E$2,$BQ$2:$CB$530,ROW()-1,0)-HLOOKUP($E$2,$DA$2:$DL$437,ROW()-1,0) -> #N/A | CQ14: =IFERROR(HLOOKUP($E$2,$BQ$2:$CB$530,ROW()-1,0)/HLOOKUP($E$2,$DA$2:$DL$437,ROW()-1,0),0) -> 0 | CR14: =CE14-CD14 -> -60.504573 | CS14: =CE14-BR14 -> -45.760446 | CU14: =SUM(CD14:CO14) -> 256.70963 | CV14: =CU14-SUM(DA14:DB14) -> 256.70963 | CW14: =IFERROR(CU14/SUM(DA14:DB14),0) -> 0 | CX14: =SUM(CD14:CE14)-SUM(BQ14:BR14) -> 22.718057 | CZ14: =D14 -> 무선 | DM14: =SUM(DA14:DL14) -> 0
D15: 유선 | E15: 유선 판매 수수료 | F15: 3.7536557 | G15: -0.51352352 | H15: 7.8944597 | I15: 5.0845308 | J15: -0.25798884 | K15: 3.6902117 | L15: 4.003031 | M15: 4.8003138 | N15: 2.7976966 | O15: 4.996032 | P15: 2.6744399 | Q15: 2.6279369 | R15: 6.4691447 | S15: 0.29092113 | T15: -3.6678775 | U15: 2.7421374 | V15: 3.1083499 | W15: 3.9224924 | X15: 2.1399998 | Y15: 1.2848809 | Z15: 4.2408331 | AA15: 5.323225 | AB15: 5.1651081 | AC15: 1.453318 | AD15: 4.308168 | AE15: 3.4596139 | AF15: -2.0411117 | AG15: 4.9382714 | AH15: 2.083613 | AI15: 0.66819369 | AJ15: -0.81701071 | AK15: 4.8598722 | AL15: 12.265394 | AM15: 5.0472908 | AN15: -0.86598039 | AO15: -3.8787438 | AQ15: 0.32186282 | AR15: 4.6769718 | AS15: 1.4294523 | AT15: 4.1119909 | AU15: 2.6394275 | AV15: -0.05449167 | AW15: -3.0271059 | AX15: 5.9480626 | AY15: -4.9910422 | AZ15: 0.14376036 | BA15: -0.51294951 | BB15: -0.15039681 | BC15: 10.535542 | BD15: 6.6299536 | BE15: -2.2929907 | BF15: 11.659343 | BG15: 11.345532 | BH15: 13.185732 | BI15: 13.079573 | BJ15: 10.974492 | BK15: 2.6085677 | BL15: 12.941643 | BM15: =4.68660113 -> 4.6866011 | BN15: 5.7800246 | BO15: 6.4219598 | BP15: 97.020432 | BQ15: 5.6558239 | BR15: 22.761839 | BS15: 8.3621768 | BT15: 9.4018754 | BU15: 18.188465 | BV15: -0.19308902 | BW15: 19.370863 | BX15: 3.9176511 | BY15: 15.108351 | BZ15: 3.9154514 | CA15: 11.308556 | CB15: 22.269248 | CC15: =SUM(BQ15:CB15) -> 140.06721 | CD15: 18.609364 | CE15: 16.295959 | CP15: =HLOOKUP($E$2,$BQ$2:$CB$530,ROW()-1,0)-HLOOKUP($E$2,$DA$2:$DL$437,ROW()-1,0) -> #N/A | CQ15: =IFERROR(HLOOKUP($E$2,$BQ$2:$CB$530,ROW()-1,0)/HLOOKUP($E$2,$DA$2:$DL$437,ROW()-1,0),0) -> 0 | CR15: =CE15-CD15 -> -2.3134058 | CS15: =CE15-BR15 -> -6.4658808 | CU15: =SUM(CD15:CO15) -> 34.905323 | CV15: =CU15-SUM(DA15:DB15) -> 34.905323 | CW15: =IFERROR(CU15/SUM(DA15:DB15),0) -> 0 | CX15: =SUM(CD15:CE15)-SUM(BQ15:BR15) -> 6.4876597 | CZ15: =D15 -> 유선 | DM15: =SUM(DA15:DL15) -> 0
C16: 채널 | D16: 소매 | AQ16: 65.196455 | AR16: 101.14363 | AS16: 83.760335 | AT16: 86.435155 | AU16: 88.062806 | AV16: 86.666751 | AW16: 68.686928 | AX16: 136.5872 | AY16: 53.766598 | AZ16: 99.132962 | BA16: 63.846133 | BB16: 50.376419 | BC16: 983.66137 | BD16: =BD91 -> 119.22844 | BE16: =BE91 -> 76.720495 | BF16: =BF91 -> 78.067282 | BG16: =BG91 -> 76.931196 | BH16: =BH91 -> 76.158188 | BI16: =BI91 -> 74.807018 | BJ16: =BJ91 -> 133.57699 | BK16: =BK91 -> 87.913465 | ... BO16: =BO91 -> 64.713366 | BP16: 1062.1937 | BQ16: 49.550632 | BR16: 135.13312 | BS16: 97.077539 | BT16: 93.319228 | BU16: 120.71904 | BV16: 87.744517 | BW16: 170.4394 | BX16: 100.73824 | BY16: 110.14979 | BZ16: 79.773004 | CA16: 66.225831 | CB16: 63.352057 | CC16: =SUM(BQ16:CB16) -> 1174.2224 | CD16: 89.842143 | CE16: 59.523254 | CR16: =CE16-CD16 -> -30.318889 | CS16: =CE16-BR16 -> -75.609866 | CU16: =SUM(CD16:CO16) -> 149.3654 | CX16: =SUM(CD16:CE16)-SUM(BQ16:BR16) -> -35.318355 | CZ16: =D16 -> 소매 | DM16: =SUM(DA16:DL16) -> 0
D17: 도매 | AQ17: 79.726588 | AR17: 101.15129 | AS17: 75.106436 | AT17: 81.720367 | AU17: 74.699835 | AV17: 71.695196 | AW17: 88.783247 | AX17: 121.17301 | AY17: 87.086654 | AZ17: 95.300378 | BA17: 75.28841 | BB17: 64.490088 | BC17: 1016.2215 | BD17: =BD112 -> 93.681877 | BE17: =BE112 -> 62.089301 | BF17: =BF112 -> 49.030872 | BG17: =BG112 -> 51.625609 | BH17: =BH112 -> 47.577182 | BI17: =BI112 -> 47.880171 | BJ17: =BJ112 -> 50.827455 | BK17: =BK112 -> 30.005934 | ... BO17: =BO112 -> 7.2124588 | BP17: 475.92214 | BQ17: 1.8922512 | BR17: 2.4818942 | BS17: 0.70588278 | BT17: 3.8676704 | BU17: 0.20809046 | BV17: 0.95145149 | BW17: 1.1885326 | BX17: 0.66414166 | BY17: 2.6811764 | BZ17: -1.4387479 | CA17: 0.55627283 | CB17: 0.80422348 | CC17: =SUM(BQ17:CB17) -> 14.56284 | CD17: 1.1673652 | CE17: 0.88786531 | CR17: =CE17-CD17 -> -0.27949987 | CS17: =CE17-BR17 -> -1.5940289 | CU17: =SUM(CD17:CO17) -> 2.0552305 | CX17: =SUM(CD17:CE17)-SUM(BQ17:BR17) -> -2.3189149 | CZ17: =D17 -> 도매 | DM17: =SUM(DA17:DL17) -> 0
D18: 디지털 | AQ18: 2.2492078 | AR18: 15.326399 | AS18: 9.9789229 | AT18: 8.0602549 | AU18: 10.574179 | AV18: 11.279598 | AW18: 9.417566 | AX18: 22.97286 | AY18: 2.5173947 | AZ18: 20.538734 | BA18: 10.856837 | BB18: 10.036641 | BC18: 133.80859 | BD18: =BD160 -> 15.268876 | BE18: =BE160 -> 9.5661362 | BF18: =BF160 -> 13.166033 | BG18: =BG160 -> 13.427009 | BH18: =BH160 -> 18.838185 | BI18: =BI160 -> 11.711347 | BJ18: =BJ160 -> 18.233952 | BK18: =BK160 -> 13.102901 | ... BO18: =BO160 -> 11.927291 | BP18: 188.32789 | BQ18: 24.53915 | BR18: 24.976993 | BS18: 8.5582728 | BT18: 10.236852 | BU18: 13.668366 | BV18: 22.241117 | BW18: 45.687561 | BX18: 35.560174 | BY18: 53.929139 | BZ18: 45.383742 | CA18: 37.088443 | CB18: 42.187589 | CC18: =SUM(BQ18:CB18) -> 364.0574 | CD18: 53.249711 | CE18: 34.354444 | CR18: =CE18-CD18 -> -18.895268 | CS18: =CE18-BR18 -> 9.3774504 | CU18: =SUM(CD18:CO18) -> 87.604155 | CX18: =SUM(CD18:CE18)-SUM(BQ18:BR18) -> 38.088012 | CZ18: =D18 -> 디지털 | DM18: =SUM(DA18:DL18) -> 0
C19: 신사업 제외 | D19: 기타 | E19: B2B, 대형마트, 소상공인(25년~) | AQ19: -14.95239 | AR19: 20.654254 | AS19: 6.5305215 | AT19: 23.230123 | AU19: 26.516638 | AV19: 49.049275 | AW19: 29.098264 | AX19: 40.529453 | AY19: 51.771138 | AZ19: 44.569634 | BA19: 27.532634 | BB19: 58.175623 | BC19: 362.70517 | BD19: 11.685522 | BE19: 5.1762131 | BF19: 8.9916792 | BG19: 13.135548 | BH19: 10.677747 | BI19: 10.078795 | BJ19: 35.617728 | BK19: 14.76793 | BL19: 32.623446 | BM19: 30.549017 | BN19: 19.268505 | BO19: 20.268505 | BP19: 212.84063 | BQ19: 18.417866 | BR19: 28.322453 | BS19: 23.0726 | BT19: 21.997285 | BU19: 29.546987 | BV19: 48.038093 | BW19: 41.151348 | BX19: 31.09945 | BY19: 40.848417 | BZ19: 24.811002 | CA19: 51.910727 | CB19: 35.002715 | CC19: =SUM(BQ19:CB19) -> 394.21894 | CD19: 37.626064 | CE19: 32.749709 | CR19: =CE19-CD19 -> -4.8763545 | CS19: =CE19-BR19 -> 4.4272565 | CU19: =SUM(CD19:CO19) -> 70.375773 | CX19: =SUM(CD19:CE19)-SUM(BQ19:BR19) -> 23.635454 | CZ19: =D19 -> 기타 | DM19: =SUM(DA19:DL19) -> 0
D20: 순액처리 | AQ20: -92.290107 | AR20: -112.08824 | AS20: -96.888933 | AT20: -92.899153 | AU20: -92.405679 | AV20: -91.720055 | AW20: -101.2654 | AX20: -144.66518 | AY20: -96.127929 | AZ20: -113.53647 | BA20: -97.03606 | BB20: -78.02788 | BC20: -1208.9511 | BD20: =BD13-BD16-BD17-BD18-BD19 -> -90.713432 | BE20: =BE13-BE16-BE17-BE18-BE19 -> -65.15814 | BF20: =BF13-BF16-BF17-BF18-BF19 -> -50.508804 | BG20: =BG13-BG16-BG17-BG18-BG19 -> -51.01704 | BH20: =BH13-BH16-BH17-BH18-BH19 -> -54.778018 | BI20: =BI13-BI16-BI17-BI18-BI19 -> -54.246445 | BJ20: =BJ13-BJ16-BJ17-BJ18-BJ19 -> -71.033397 | BK20: =BK13-BK16-BK17-BK18-BK19 -> -45.47202 | ... BO20: =BO13-BO16-BO17-BO18-BO19 -> 8.928025 | BP20: -560.1592 | BQ20: =BQ13-BQ16-BQ17-BQ18-BQ19 -> 1.3845247 | BR20: =BR13-BR16-BR17-BR18-BR19 -> -24.289645 | BS20: =BS13-BS16-BS17-BS18-BS19 -> -19.1521 | BT20: =BT13-BT16-BT17-BT18-BT19 -> -25.421259 | BU20: =BU13-BU16-BU17-BU18-BU19 -> -22.867412 | BV20: =BV13-BV16-BV17-BV18-BV19 -> -37.259143 | BW20: =BW13-BW16-BW17-BW18-BW19 -> -36.389221 | BX20: =BX13-BX16-BX17-BX18-BX19 -> -33.065445 | ... CB20: =CB13-CB16-CB17-CB18-CB19 -> 42.385013 | CC20: =SUM(BQ20:CB20) -> -218.02947 | CD20: =CD13-CD16-CD17-CD18-CD19 -> -4.6688159 | CE20: =CE13-CE16-CE17-CE18-CE19 -> -13.116784 | CR20: =CE20-CD20 -> -8.4479679 | CS20: =CE20-BR20 -> 11.172861 | CU20: =SUM(CD20:CO20) -> -17.7856 | CX20: =SUM(CD20:CE20)-SUM(BQ20:BR20) -> 5.1195205 | CZ20: =D20 -> 순액처리 | DM20: =SUM(DA20:DL20) -> 0
C21: 관리수수료 | F21: 38.873879 | G21: 40.31233 | H21: 42.252128 | I21: 39.439889 | J21: 43.59426 | K21: 40.877616 | L21: 41.065562 | M21: 44.865416 | N21: 42.496813 | O21: 43.838211 | P21: 40.671535 | Q21: 42.174853 | R21: 41.181559 | S21: 46.179168 | T21: 43.562214 | U21: 52.91949 | V21: 46.568344 | W21: 47.585661 | X21: 46.753641 | Y21: 49.665687 | Z21: 46.422716 | AA21: 49.670652 | AB21: 50.46602 | AC21: 48.955665 | AD21: 50.46 | AE21: 52.316195 | AF21: 52.320335 | AG21: 49.76926 | AH21: 52.548349 | AI21: 52.622964 | AJ21: 54.929105 | AK21: 55.58836 | AL21: 54.052958 | AM21: 45.170608 | AN21: 56.900435 | AO21: 48.675597 | AQ21: 67.035032 | AR21: 50.863376 | AS21: 59.716036 | AT21: 55.567621 | AU21: 58.716059 | AV21: 57.914679 | AW21: 60.555175 | AX21: 58.62319 | AY21: 53.750966 | AZ21: 60.481486 | BA21: 55.964691 | BB21: 61.162647 | BC21: 700.35096 | BD21: 59.825449 | BE21: 58.204345 | BF21: 57.755821 | BG21: 55.445384 | BH21: 55.358037 | BI21: 55.127947 | BJ21: 57.009085 | BK21: 55.188602 | BL21: 53.705683 | BM21: 60.367561 | BN21: 50.24477 | BO21: 67.090589 | BP21: 685.32327 | BQ21: 49.926384 | BR21: 52.970258 | BS21: 49.264715 | BT21: 56.60334 | BU21: 46.224101 | BV21: 59.260522 | BW21: 53.276578 | BX21: 50.293206 | BY21: 52.541221 | BZ21: 44.020952 | CA21: 50.254107 | CB21: 51.007165 | CC21: =SUM(BQ21:CB21) -> 615.64255 | CD21: 49.896065 | CE21: 48.946021 | CP21: =HLOOKUP($E$2,$BQ$2:$CB$530,ROW()-1,0)-HLOOKUP($E$2,$DA$2:$DL$437,ROW()-1,0) -> #N/A | CQ21: =IFERROR(HLOOKUP($E$2,$BQ$2:$CB$530,ROW()-1,0)/HLOOKUP($E$2,$DA$2:$DL$437,ROW()-1,0),0) -> 0 | CR21: =CE21-CD21 -> -0.9500441 | CS21: =CE21-BR21 -> -4.0242364 | CU21: =SUM(CD21:CO21) -> 98.842087 | CV21: =CU21-SUM(DA21:DB21) -> 98.842087 | CW21: =IFERROR(CU21/SUM(DA21:DB21),0) -> 0 | CX21: =SUM(CD21:CE21)-SUM(BQ21:BR21) -> -4.0545552 | CZ21: =C21 -> 관리수수료 | DM21: =SUM(DA21:DL21) -> 0
